{"registryname": "corrupted_starfactory",
"localizedname": "Corrupted Starfactory",
"color":"262626",
    "parts": [
        {
            "x": -1,
            "y": 0,
            "z": 0,
            
            "elements": [
                "modularmachinery:blockcasing@4"
            ]
        },
        {
            "x": 1,
            "y": 2,
            "z": 1,
            "elements": [
                "chisel:redstone1@2"
            ]
        },
        {
            "x": 2,
            "y": 2,
            "z": 1,
            
            "elements": [
                "modularmachinery:blockcasing@4"
            ]
        },
        {
            "x": 1,
            "y": 0,
            "z": 0,
            
            "elements": [
                "modularmachinery:blockinputbus@1"
            ]
        },
        {
            "x": 2,
            "y": 0,
            "z": 0,
            
            "elements": [
                "modularmachinery:blockcasing@4"
            ]
        },
        {
            "x": -1,
            "y": 0,
            "z": 8,
            
            "elements": [
                "modularmachinery:blockcasing@4"
            ]
        },
        {
            "x": 0,
            "y": 0,
            "z": 8,
            
            "elements": [
                "modularmachinery:blockcasing@4"
            ]
        },
        {
            "x": 1,
            "y": 0,
            "z": 8,
            "elements": [
                "chisel:redstone1@2"
            ]
        },
        {
            "x": 2,
            "y": 0,
            "z": 8,
            
            "elements": [
                "modularmachinery:blockcasing@4"
            ]
        },
        {
            "x": 2,
            "y": -1,
            "z": 0,
            
            "elements": [
                "modularmachinery:blockcasing@0"
            ]
        },
        {
            "x": 1,
            "y": -1,
            "z": 0,
            
            "elements": [
                "modularmachinery:blockoutputbus@1"
            ]
        },
        {
            "x": 0,
            "y": -1,
            "z": 0,
            "elements": [
                "chisel:redstone1@2"
            ]
        },
        {
            "x": -1,
            "y": 1,
            "z": 0,
            "elements": [
                "chisel:redstone1@2"
            ]
        },
        {
            "x": 0,
            "y": 1,
            "z": 0,
            "elements": [
                "chisel:redstone1@2"
            ]
        },
        {
            "x": -1,
            "y": -1,
            "z": 0,
            "elements": [
                "chisel:redstone1@2"
            ]
        },
        {
            "x": 1,
            "y": 1,
            "z": 0,
            "elements": [
                "chisel:diamond@4"
            ]
        },
        {
            "x": 2,
            "y": 1,
            "z": 0,
            "elements": [
                "chisel:redstone1@2"
            ]
        },
        {
            "x": -2,
            "y": -1,
            "z": 7,
            "elements": [
                "chisel:redstone1@2"
            ]
        },
        {
            "x": -1,
            "y": 1,
            "z": 8,
            "elements": [
                "chisel:redstone1@2"
            ]
        },
        {
            "x": 0,
            "y": 1,
            "z": 8,
            
            "elements": [
                "modularmachinery:blockcasing@0"
            ]
        },
        {
            "x": 1,
            "y": 1,
            "z": 8,
            "elements": [
                "chisel:diamond@4"
            ]
        },
        {
            "x": 2,
            "y": 1,
            "z": 8,
            
            "elements": [
                "modularmachinery:blockcasing@0"
            ]
        },
        {
            "x": 3,
            "y": -1,
            "z": 7,
            
            "elements": [
                "modularmachinery:blockcasing@0"
            ]
        },
        {
            "x": -2,
            "y": 0,
            "z": 7,
            
            "elements": [
                "modularmachinery:blockcasing@4"
            ]
        },
        {
            "x": -1,
            "y": 0,
            "z": 7,
            
            "elements": [
                "projectex:relay@15"
            ]
        },
        {
            "x": 0,
            "y": 0,
            "z": 7,
            
            "elements": [
                "projectex:collector@15"
            ]
        },
        {
            "x": 1,
            "y": 0,
            "z": 7,
            
            "elements": [
                "projectex:collector@15"
            ]
        },
        {
            "x": 2,
            "y": 0,
            "z": 7,
            
            "elements": [
                "projectex:relay@15"
            ]
        },
        {
            "x": 3,
            "y": 0,
            "z": 7,
            
            "elements": [
                "modularmachinery:blockcasing@4"
            ]
        },
        {
            "x": -3,
            "y": -1,
            "z": 6,
            
            "elements": [
                "modularmachinery:blockcasing@0"
            ]
        },
        {
            "x": -2,
            "y": 1,
            "z": 7,
            "elements": [
                "chisel:redstone1@2"
            ]
        },
        {
            "x": -1,
            "y": 1,
            "z": 7,
            
            "elements": [
                "projectex:relay@15"
            ]
        },
        {
            "x": 0,
            "y": 1,
            "z": 7,
            
            "elements": [
                "projectex:collector@15"
            ]
        },
        {
            "x": -1,
            "y": -1,
            "z": 6,
            
            "elements": [
                "projectex:relay@15"
            ]
        },
        {
            "x": 0,
            "y": -1,
            "z": 6,
            
            "elements": [
                "projectex:relay@15"
            ]
        },
        {
            "x": 1,
            "y": 1,
            "z": 7,
            
            "elements": [
                "projectex:collector@15"
            ]
        },
        {
            "x": 2,
            "y": 1,
            "z": 7,
            
            "elements": [
                "projectex:relay@15"
            ]
        },
        {
            "x": 1,
            "y": -1,
            "z": 6,
            
            "elements": [
                "projectex:relay@15"
            ]
        },
        {
            "x": 3,
            "y": 1,
            "z": 7,
            "elements": [
                "chisel:redstone1@2"
            ]
        },
        {
            "x": 2,
            "y": -1,
            "z": 6,
            
            "elements": [
                "projectex:relay@15"
            ]
        },
        {
            "x": 4,
            "y": -1,
            "z": 6,
            "elements": [
                "chisel:redstone1@2"
            ]
        },
        {
            "x": -3,
            "y": 0,
            "z": 6,
            "elements": [
                "chisel:redstone1@2"
            ]
        },
        {
            "x": -2,
            "y": 0,
            "z": 6,
            
            "elements": [
                "projectex:relay@15"
            ]
        },
        {
            "x": -1,
            "y": 2,
            "z": 7,
            
            "elements": [
                "modularmachinery:blockcasing@0"
            ]
        },
        {
            "x": 0,
            "y": 2,
            "z": 7,
            "elements": [
                "chisel:redstone1@2"
            ]
        },
        {
            "x": 1,
            "y": 2,
            "z": 7,
            
            "elements": [
                "modularmachinery:blockcasing@0"
            ]
        },
        {
            "x": 2,
            "y": 2,
            "z": 7,
            
            "elements": [
                "modularmachinery:blockcasing@0"
            ]
        },
        {
            "x": 3,
            "y": 0,
            "z": 6,
            
            "elements": [
                "projectex:relay@15"
            ]
        },
        {
            "x": 4,
            "y": 0,
            "z": 6,
            
            "elements": [
                "modularmachinery:blockcasing@4"
            ]
        },
        {
            "x": -4,
            "y": -1,
            "z": 5,
            "elements": [
                "chisel:diamond@4"
            ]
        },
        {
            "x": -3,
            "y": 1,
            "z": 6,
            "elements": [
                "chisel:diamond@4"
            ]
        },
        {
            "x": -2,
            "y": 1,
            "z": 6,
            
            "elements": [
                "projectex:relay@15"
            ]
        },
        {
            "x": -2,
            "y": -1,
            "z": 5,
            
            "elements": [
                "projectex:relay@15"
            ]
        },
        {
            "x": -1,
            "y": -1,
            "z": 5,
            
            "elements": [
                "projectex:relay@15"
            ]
        },
        {
            "x": 0,
            "y": -1,
            "z": 5,
            
            "elements": [
                "projectex:collector@15"
            ]
        },
        {
            "x": 1,
            "y": -1,
            "z": 5,
            
            "elements": [
                "projectex:collector@15"
            ]
        },
        {
            "x": 3,
            "y": 1,
            "z": 6,
            
            "elements": [
                "projectex:relay@15"
            ]
        },
        {
            "x": 2,
            "y": -1,
            "z": 5,
            
            "elements": [
                "projectex:relay@15"
            ]
        },
        {
            "x": 4,
            "y": 1,
            "z": 6,
            "elements": [
                "chisel:redstone1@2"
            ]
        },
        {
            "x": 3,
            "y": -1,
            "z": 5,
            
            "elements": [
                "projectex:relay@15"
            ]
        },
        {
            "x": 5,
            "y": -1,
            "z": 5,
            
            "elements": [
                "modularmachinery:blockcasing@0"
            ]
        },
        {
            "x": -4,
            "y": 0,
            "z": 5,
            
            "elements": [
                "modularmachinery:blockcasing@4"
            ]
        },
        {
            "x": -3,
            "y": 0,
            "z": 5,
            
            "elements": [
                "projectex:relay@15"
            ]
        },
        {
            "x": -2,
            "y": 2,
            "z": 6,
            
            "elements": [
                "modularmachinery:blockcasing@0"
            ]
        },
        {
            "x": -1,
            "y": 2,
            "z": 6,
            
            "elements": [
                "projectex:collector@15"
            ]
        },
        {
            "x": 0,
            "y": 2,
            "z": 6,
            
            "elements": [
                "projectex:collector@15"
            ]
        },
        {
            "x": 1,
            "y": 2,
            "z": 6,
            
            "elements": [
                "projectex:collector@15"
            ]
        },
        {
            "x": 2,
            "y": 2,
            "z": 6,
            
            "elements": [
                "projectex:collector@15"
            ]
        },
        {
            "x": 3,
            "y": 2,
            "z": 6,
            
            "elements": [
                "modularmachinery:blockcasing@0"
            ]
        },
        {
            "x": 4,
            "y": 0,
            "z": 5,
            
            "elements": [
                "projectex:relay@15"
            ]
        },
        {
            "x": 5,
            "y": 0,
            "z": 5,
            
            "elements": [
                "modularmachinery:blockcasing@4"
            ]
        },
        {
            "x": -4,
            "y": 1,
            "z": 5,
            
            "elements": [
                "modularmachinery:blockcasing@0"
            ]
        },
        {
            "x": -4,
            "y": -1,
            "z": 4,
            "elements": [
                "chisel:redstone1@2"
            ]
        },
        {
            "x": -3,
            "y": 1,
            "z": 5,
            
            "elements": [
                "projectex:relay@15"
            ]
        },
        {
            "x": -1,
            "y": 3,
            "z": 6,
            "elements": [
                "chisel:redstone1@2"
            ]
        },
        {
            "x": 0,
            "y": 3,
            "z": 6,
            
            "elements": [
                "modularmachinery:blockcasing@0"
            ]
        },
        {
            "x": -2,
            "y": -1,
            "z": 4,
            
            "elements": [
                "projectex:relay@15"
            ]
        },
        {
            "x": 1,
            "y": 3,
            "z": 6,
            "elements": [
                "chisel:redstone1@2"
            ]
        },
        {
            "x": -1,
            "y": -1,
            "z": 4,
            
            "elements": [
                "projectex:relay@15"
            ]
        },
        {
            "x": 0,
            "y": -1,
            "z": 4,
            
            "elements": [
                "projectex:collector@15"
            ]
        },
        {
            "x": 2,
            "y": 3,
            "z": 6,
            
            "elements": [
                "modularmachinery:blockcasing@0"
            ]
        },
        {
            "x": 1,
            "y": -1,
            "z": 4,
            
            "elements": [
                "projectex:collector@15"
            ]
        },
        {
            "x": 2,
            "y": -1,
            "z": 4,
            
            "elements": [
                "projectex:relay@15"
            ]
        },
        {
            "x": 4,
            "y": 1,
            "z": 5,
            
            "elements": [
                "projectex:relay@15"
            ]
        },
        {
            "x": 3,
            "y": -1,
            "z": 4,
            
            "elements": [
                "projectex:relay@15"
            ]
        },
        {
            "x": 5,
            "y": 1,
            "z": 5,
            "elements": [
                "chisel:redstone1@2"
            ]
        },
        {
            "x": 5,
            "y": -1,
            "z": 4,
            
            "elements": [
                "modularmachinery:blockcasing@0"
            ]
        },
        {
            "x": -4,
            "y": 0,
            "z": 4,
            
            "elements": [
                "modularmachinery:blockcasing@4"
            ]
        },
        {
            "x": -3,
            "y": 2,
            "z": 5,
            
            "elements": [
                "modularmachinery:blockcasing@0"
            ]
        },
        {
            "x": -3,
            "y": 0,
            "z": 4,
            
            "elements": [
                "projectex:collector@15"
            ]
        },
        {
            "x": -2,
            "y": 2,
            "z": 5,
            
            "elements": [
                "projectex:collector@15"
            ]
        },
        {
            "x": 3,
            "y": 2,
            "z": 5,
            
            "elements": [
                "projectex:collector@15"
            ]
        },
        {
            "x": 4,
            "y": 2,
            "z": 5,
            "elements": [
                "chisel:diamond@4"
            ]
        },
        {
            "x": 4,
            "y": 0,
            "z": 4,
            
            "elements": [
                "projectex:collector@15"
            ]
        },
        {
            "x": 5,
            "y": 0,
            "z": 4,
            
            "elements": [
                "modularmachinery:blockcasing@4"
            ]
        },
        {
            "x": -4,
            "y": 1,
            "z": 4,
            "elements": [
                "chisel:redstone1@2"
            ]
        },
        {
            "x": -4,
            "y": -1,
            "z": 3,
            
            "elements": [
                "modularmachinery:blockcasing@0"
            ]
        },
        {
            "x": -3,
            "y": 1,
            "z": 4,
            
            "elements": [
                "projectex:collector@15"
            ]
        },
        {
            "x": -2,
            "y": 3,
            "z": 5,
            "elements": [
                "chisel:redstone1@2"
            ]
        },
        {
            "x": -1,
            "y": 3,
            "z": 5,
            
            "elements": [
                "projectex:relay@15"
            ]
        },
        {
            "x": 0,
            "y": 3,
            "z": 5,
            
            "elements": [
                "projectex:relay@15"
            ]
        },
        {
            "x": -2,
            "y": -1,
            "z": 3,
            
            "elements": [
                "projectex:relay@15"
            ]
        },
        {
            "x": 1,
            "y": 3,
            "z": 5,
            
            "elements": [
                "projectex:relay@15"
            ]
        },
        {
            "x": -1,
            "y": -1,
            "z": 3,
            
            "elements": [
                "projectex:relay@15"
            ]
        },
        {
            "x": 0,
            "y": -1,
            "z": 3,
            
            "elements": [
                "projectex:collector@15"
            ]
        },
        {
            "x": 2,
            "y": 3,
            "z": 5,
            
            "elements": [
                "projectex:relay@15"
            ]
        },
        {
            "x": 3,
            "y": 3,
            "z": 5,
            "elements": [
                "chisel:redstone1@2"
            ]
        },
        {
            "x": 1,
            "y": -1,
            "z": 3,
            
            "elements": [
                "projectex:collector@15"
            ]
        },
        {
            "x": 2,
            "y": -1,
            "z": 3,
            
            "elements": [
                "projectex:relay@15"
            ]
        },
        {
            "x": 4,
            "y": 1,
            "z": 4,
            
            "elements": [
                "projectex:collector@15"
            ]
        },
        {
            "x": 3,
            "y": -1,
            "z": 3,
            
            "elements": [
                "projectex:relay@15"
            ]
        },
        {
            "x": 5,
            "y": 1,
            "z": 4,
            
            "elements": [
                "modularmachinery:blockcasing@0"
            ]
        },
        {
            "x": 5,
            "y": -1,
            "z": 3,
            "elements": [
                "chisel:redstone1@2"
            ]
        },
        {
            "x": -4,
            "y": 0,
            "z": 3,
            "elements": [
                "chisel:redstone1@2"
            ]
        },
        {
            "x": -3,
            "y": 2,
            "z": 4,
            "elements": [
                "chisel:redstone1@2"
            ]
        },
        {
            "x": -3,
            "y": 0,
            "z": 3,
            
            "elements": [
                "projectex:relay@15"
            ]
        },
        {
            "x": -2,
            "y": 2,
            "z": 4,
            
            "elements": [
                "projectex:collector@15"
            ]
        },
        {
            "x": -1,
            "y": 4,
            "z": 5,
            
            "elements": [
                "modularmachinery:blockcasing@4"
            ]
        },
        {
            "x": 0,
            "y": 4,
            "z": 5,
            "elements": [
                "chisel:redstone1@2"
            ]
        },
        {
            "x": 1,
            "y": 4,
            "z": 5,
            "elements": [
                "chisel:redstone1@2"
            ]
        },
        {
            "x": 2,
            "y": 4,
            "z": 5,
            
            "elements": [
                "modularmachinery:blockcasing@4"
            ]
        },
        {
            "x": 3,
            "y": 2,
            "z": 4,
            
            "elements": [
                "projectex:collector@15"
            ]
        },
        {
            "x": 4,
            "y": 2,
            "z": 4,
            "elements": [
                "chisel:redstone1@2"
            ]
        },
        {
            "x": 4,
            "y": 0,
            "z": 3,
            
            "elements": [
                "projectex:relay@15"
            ]
        },
        {
            "x": 5,
            "y": 0,
            "z": 3,
            "elements": [
                "chisel:redstone1@2"
            ]
        },
        {
            "x": -4,
            "y": 1,
            "z": 3,
            
            "elements": [
                "modularmachinery:blockcasing@0"
            ]
        },
        {
            "x": -3,
            "y": 1,
            "z": 3,
            
            "elements": [
                "projectex:relay@15"
            ]
        },
        {
            "x": -2,
            "y": 3,
            "z": 4,
            
            "elements": [
                "modularmachinery:blockcasing@0"
            ]
        },
        {
            "x": -3,
            "y": -1,
            "z": 2,
            "elements": [
                "chisel:redstone1@2"
            ]
        },
        {
            "x": -1,
            "y": 3,
            "z": 4,
            
            "elements": [
                "projectex:relay@15"
            ]
        },
        {
            "x": -1,
            "y": -1,
            "z": 2,
            
            "elements": [
                "projectex:relay@15"
            ]
        },
        {
            "x": 0,
            "y": -1,
            "z": 2,
            
            "elements": [
                "projectex:relay@15"
            ]
        },
        {
            "x": 2,
            "y": 3,
            "z": 4,
            
            "elements": [
                "projectex:relay@15"
            ]
        },
        {
            "x": 3,
            "y": 3,
            "z": 4,
            
            "elements": [
                "modularmachinery:blockcasing@0"
            ]
        },
        {
            "x": 1,
            "y": -1,
            "z": 2,
            
            "elements": [
                "projectex:relay@15"
            ]
        },
        {
            "x": 2,
            "y": -1,
            "z": 2,
            
            "elements": [
                "projectex:relay@15"
            ]
        },
        {
            "x": 4,
            "y": 1,
            "z": 3,
            
            "elements": [
                "projectex:relay@15"
            ]
        },
        {
            "x": 5,
            "y": 1,
            "z": 3,
            "elements": [
                "chisel:redstone1@2"
            ]
        },
        {
            "x": 4,
            "y": -1,
            "z": 2,
            
            "elements": [
                "modularmachinery:blockcasing@0"
            ]
        },
        {
            "x": -3,
            "y": 2,
            "z": 3,
            
            "elements": [
                "modularmachinery:blockcasing@0"
            ]
        },
        {
            "x": -3,
            "y": 0,
            "z": 2,
            
            "elements": [
                "modularmachinery:blockcasing@4"
            ]
        },
        {
            "x": -2,
            "y": 2,
            "z": 3,
            
            "elements": [
                "projectex:collector@15"
            ]
        },
        {
            "x": -1,
            "y": 4,
            "z": 4,
            
            "elements": [
                "modularmachinery:blockcasing@4"
            ]
        },
        {
            "x": 0,
            "y": 4,
            "z": 4,
            
            "elements": [
                "modularmachinery:blockfluidinputhatch@2"
            ]
        },
        {
            "x": -2,
            "y": 0,
            "z": 2,
            
            "elements": [
                "projectex:relay@15"
            ]
        },
        {
            "x": 1,
            "y": 4,
            "z": 4,
        
            "elements": [
                "modularmachinery:blockfluidinputhatch@2"
            ]
        },
        {
            "x": 2,
            "y": 4,
            "z": 4,
            
            "elements": [
                "modularmachinery:blockcasing@4"
            ]
        },
        {
            "x": 3,
            "y": 2,
            "z": 3,
            
            "elements": [
                "projectex:collector@15"
            ]
        },
        {
            "x": 4,
            "y": 2,
            "z": 3,
            "elements": [
                "chisel:diamond@4"
            ]
        },
        {
            "x": 3,
            "y": 0,
            "z": 2,
            
            "elements": [
                "projectex:relay@15"
            ]
        },
        {
            "x": 4,
            "y": 0,
            "z": 2,
            
            "elements": [
                "modularmachinery:blockcasing@4"
            ]
        },
        {
            "x": -3,
            "y": 1,
            "z": 2,
            "elements": [
                "chisel:redstone1@2"
            ]
        },
        {
            "x": -2,
            "y": 3,
            "z": 3,
            "elements": [
                "chisel:redstone1@2"
            ]
        },
        {
            "x": -2,
            "y": 1,
            "z": 2,
            
            "elements": [
                "projectex:relay@15"
            ]
        },
        {
            "x": -1,
            "y": 3,
            "z": 3,
            
            "elements": [
                "projectex:relay@15"
            ]
        },
        {
            "x": 0,
            "y": 3,
            "z": 3,
            
            "elements": [
                "projectex:relay@15"
            ]
        },
        {
            "x": -2,
            "y": -1,
            "z": 1,
            "elements": [
                "chisel:diamond@4"
            ]
        },
        {
            "x": 1,
            "y": 3,
            "z": 3,
            
            "elements": [
                "projectex:relay@15"
            ]
        },
        {
            "x": 2,
            "y": 3,
            "z": 3,
            
            "elements": [
                "projectex:relay@15"
            ]
        },
        {
            "x": 3,
            "y": 3,
            "z": 3,
            "elements": [
                "chisel:diamond@4"
            ]
        },
        {
            "x": 3,
            "y": 1,
            "z": 2,
            
            "elements": [
                "projectex:relay@15"
            ]
        },
        {
            "x": 4,
            "y": 1,
            "z": 2,
            
            "elements": [
                "modularmachinery:blockcasing@0"
            ]
        },
        {
            "x": 3,
            "y": -1,
            "z": 1,
            "elements": [
                "chisel:redstone1@2"
            ]
        },
        {
            "x": -2,
            "y": 2,
            "z": 2,
            
            "elements": [
                "modularmachinery:blockcasing@4"
            ]
        },
        {
            "x": -1,
            "y": 4,
            "z": 3,
            
            "elements": [
                "modularmachinery:blockcasing@4"
            ]
        },
        {
            "x": 0,
            "y": 4,
            "z": 3,
            
            "elements": [
                "modularmachinery:blockcasing@4"
            ]
        },
        {
            "x": -2,
            "y": 0,
            "z": 1,
            
            "elements": [
                "modularmachinery:blockcasing@4"
            ]
        },
        {
            "x": -1,
            "y": 2,
            "z": 2,
            
            "elements": [
                "projectex:collector@15"
            ]
        },
        {
            "x": 1,
            "y": 4,
            "z": 3,
            "elements": [
                "chisel:redstone1@2"
            ]
        },
        {
            "x": 0,
            "y": 2,
            "z": 2,
            
            "elements": [
                "projectex:collector@15"
            ]
        },
        {
            "x": -1,
            "y": 0,
            "z": 1,
            
            "elements": [
                "projectex:relay@15"
            ]
        },
        {
            "x": 0,
            "y": 0,
            "z": 1,
            
            "elements": [
                "projectex:collector@15"
            ]
        },
        {
            "x": 2,
            "y": 4,
            "z": 3,
            
            "elements": [
                "modularmachinery:blockcasing@4"
            ]
        },
        {
            "x": 1,
            "y": 2,
            "z": 2,
            
            "elements": [
                "projectex:collector@15"
            ]
        },
        {
            "x": 2,
            "y": 2,
            "z": 2,
            
            "elements": [
                "projectex:collector@15"
            ]
        },
        {
            "x": 1,
            "y": 0,
            "z": 1,
            
            "elements": [
                "projectex:collector@15"
            ]
        },
        {
            "x": 3,
            "y": 2,
            "z": 2,
            "elements": [
                "chisel:redstone1@2"
            ]
        },
        {
            "x": 2,
            "y": 0,
            "z": 1,
            
            "elements": [
                "projectex:relay@15"
            ]
        },
        {
            "x": 3,
            "y": 0,
            "z": 1,
            
            "elements": [
                "modularmachinery:blockcasing@4"
            ]
        },
        {
            "x": -2,
            "y": 1,
            "z": 1,
            "elements": [
                "chisel:diamond@4"
            ]
        },
        {
            "x": -1,
            "y": 3,
            "z": 2,
            "elements": [
                "chisel:redstone1@2"
            ]
        },
        {
            "x": 0,
            "y": 3,
            "z": 2,
            
            "elements": [
                "modularmachinery:blockcasing@0"
            ]
        },
        {
            "x": -1,
            "y": 1,
            "z": 1,
            
            "elements": [
                "projectex:relay@15"
            ]
        },
        {
            "x": 1,
            "y": 3,
            "z": 2,
            
            "elements": [
                "modularmachinery:blockcasing@0"
            ]
        },
        {
            "x": 0,
            "y": 1,
            "z": 1,
            
            "elements": [
                "projectex:collector@15"
            ]
        },
        {
            "x": 2,
            "y": 3,
            "z": 2,
            "elements": [
                "chisel:redstone1@2"
            ]
        },
        {
            "x": 1,
            "y": 1,
            "z": 1,
            
            "elements": [
                "projectex:collector@15"
            ]
        },
        {
            "x": 2,
            "y": 1,
            "z": 1,
            
            "elements": [
                "projectex:relay@15"
            ]
        },
        {
            "x": 3,
            "y": 1,
            "z": 1,
            "elements": [
                "chisel:redstone1@2"
            ]
        },
        {
            "x": -1,
            "y": -1,
            "z": 8,
            "elements": [
                "chisel:redstone1@2"
            ]
        },
        {
            "x": 0,
            "y": -1,
            "z": 8,
            
            "elements": [
                "modularmachinery:blockcasing@0"
            ]
        },
        {
            "x": 1,
            "y": -1,
            "z": 8,
            
            "elements": [
                "modularmachinery:blockcasing@0"
            ]
        },
        {
            "x": 2,
            "y": -1,
            "z": 8,
            "elements": [
                "chisel:redstone1@2"
            ]
        },
        {
            "x": -1,
            "y": 2,
            "z": 1,
            
            "elements": [
                "modularmachinery:blockcasing@0"
            ]
        },
        {
            "x": 0,
            "y": 2,
            "z": 1,
            
            "elements": [
                "modularmachinery:blockcasing@4"
            ]
        }
    ]}