{"registryname": "timetwisting_clocktower",
"localizedname": "Timetwisting ClockTower",
"color":"234987",
    "parts": [
        {
            "x": 2,
            "y": 4,
            "z": 2,
            "elements": [
                "modularmachinery:blockcasing@4"
            ]
        },
     {
            "x": 0,
            "y": 22,
            "z": 3,
            "elements": [
                "projecte:matter_block@0"
            ]
        },
        {
            "x": -1,
            "y": 0,
            "z": 0,
            "elements": [
                "modularmachinery:blockcasing@0"
            ]
        },
{
            "x": -1,
            "y": 16,
            "z": 2,
            "elements": [
                "chisel:antiblock@15"
            ]
        },
        {
            "x": 2,
            "y": 2,
            "z": 1,
            "elements": [
                "modularmachinery:blockcasing@4"
            ]
        },
        {
            "x": -2,
            "y": 0,
            "z": 0,
            "elements": [
                "modularmachinery:blockcasing@0"
            ]
        },
        {
            "x": 1,
            "y": 0,
            "z": 0,
            
            "elements": [
                "modularmachinery:blockcasing@0"
            ]
        },
        {
            "x": 2,
            "y": 0,
            "z": 0,
            
            "elements": [
                "modularmachinery:blockcasing@0"
            ]
        },
        {
            "x": -2,
            "y": 9,
            "z": 4,
            "elements": [
                "projecte:matter_block@0"
            ]
        },
{
            "x": -2,
            "y": 9,
            "z": 4,
            "elements": [
                "projecte:matter_block@0"
            ]
        },
        {
            "x": -1,
            "y": 9,
            "z": 4,
            
            "elements": [
                "modularmachinery:blockcasing@0"
            ]
        },
        {
            "x": -2,
            "y": 5,
            "z": 2,
            
            "elements": [
                "modularmachinery:blockcasing@4"
            ]
        },
        {
            "x": -1,
            "y": 7,
            "z": 3,
            "elements": [
                "projecte:matter_block@0"
            ]
        },
        {
            "x": 0,
            "y": 7,
            "z": 3,
            "elements": [
                "projecte:matter_block@0"
            ]
        },
        {
            "x": -2,
            "y": 3,
            "z": 1,
            
            "elements": [
                "modularmachinery:blockcasing@4"
            ]
        },
        {
            "x": 1,
            "y": 9,
            "z": 4,
            
            "elements": [
                "modularmachinery:blockcasing@0"
            ]
        },
        {
            "x": 2,
            "y": 9,
            "z": 4,
            "elements": [
                "projecte:matter_block@0"
            ]
        },
        {
            "x": 1,
            "y": 7,
            "z": 3,
            "elements": [
                "projecte:matter_block@0"
            ]
        },
        {
            "x": -2,
            "y": 1,
            "z": 0,
            
            "elements": [
                "modularmachinery:blockcasing@0"
            ]
        },
        {
            "x": -1,
            "y": 1,
            "z": 0,
            "elements": [
                "projecte:matter_block@0"
            ]
        },
        {
            "x": 2,
            "y": 5,
            "z": 2,
            
            "elements": [
                "modularmachinery:blockcasing@4"
            ]
        },
        {
            "x": 0,
            "y": 1,
            "z": 0,
            "elements": [
                "projecte:matter_block@0"
            ]
        },
        {
            "x": 2,
            "y": 3,
            "z": 1,
            
            "elements": [
                "modularmachinery:blockcasing@4"
            ]
        },
        {
            "x": 1,
            "y": 1,
            "z": 0,
            "elements": [
                "projecte:matter_block@0"
            ]
        },
        {
            "x": 2,
            "y": 1,
            "z": 0,
            
            "elements": [
                "modularmachinery:blockcasing@0"
            ]
        },
        {
            "x": -2,
            "y": 10,
            "z": 4,
            "elements": [
                "projecte:matter_block@0"
            ]
        },
        {
            "x": -1,
            "y": 10,
            "z": 4,
            
            "elements": [
                "modularmachinery:blockcasing@0"
            ]
        },
        {
            "x": -2,
            "y": 8,
            "z": 3,
            
            "elements": [
                "modularmachinery:blockcasing@0"
            ]
        },
        {
            "x": 0,
            "y": 10,
            "z": 4,
            
            "elements": [
                "modularmachinery:blockcasing@0"
            ]
        },
        {
            "x": -2,
            "y": 6,
            "z": 2,
            
            "elements": [
                "modularmachinery:blockcasing@0"
            ]
        },
        {
            "x": -1,
            "y": 6,
            "z": 2,
            "elements": [
                "projecte:matter_block@0"
            ]
        },
        {
            "x": 0,
            "y": 8,
            "z": 3,
            "elements": [
                "chisel:antiblock@15"
            ]
        },
        {
            "x": 1,
            "y": 10,
            "z": 4,
            
            "elements": [
                "modularmachinery:blockcasing@0"
            ]
        },
        {
            "x": -2,
            "y": 4,
            "z": 1,
            
            "elements": [
                "modularmachinery:blockcasing@0"
            ]
        },
        {
            "x": 2,
            "y": 10,
            "z": 4,
            "elements": [
                "projecte:matter_block@0"
            ]
        },
        {
            "x": -1,
            "y": 4,
            "z": 1,
            
            "elements": [
                "modularmachinery:blockcasing@0"
            ]
        },
        {
            "x": -2,
            "y": 2,
            "z": 0,
            
            "elements": [
                "modularmachinery:blockcasing@0"
            ]
        },
        {
            "x": 2,
            "y": 8,
            "z": 3,
            
            "elements": [
                "modularmachinery:blockcasing@0"
            ]
        },
        {
            "x": -1,
            "y": 2,
            "z": 0,
            
            "elements": [
                "modularmachinery:blockcasing@4"
            ]
        },
        {
            "x": 1,
            "y": 6,
            "z": 2,
            "elements": [
                "projecte:matter_block@0"
            ]
        },
        {
            "x": 2,
            "y": 6,
            "z": 2,
            
            "elements": [
                "modularmachinery:blockcasing@0"
            ]
        },
        {
            "x": 0,
            "y": 2,
            "z": 0,
            
            "elements": [
                "modularmachinery:blockcasing@0"
            ]
        },
        {
            "x": 1,
            "y": 4,
            "z": 1,
            
            "elements": [
                "modularmachinery:blockcasing@0"
            ]
        },
        {
            "x": 2,
            "y": 4,
            "z": 1,
            
            "elements": [
                "modularmachinery:blockcasing@0"
            ]
        },
        {
            "x": 1,
            "y": 2,
            "z": 0,
            
            "elements": [
                "modularmachinery:blockcasing@4"
            ]
        },
        {
            "x": 2,
            "y": 2,
            "z": 0,
            
            "elements": [
                "modularmachinery:blockcasing@0"
            ]
        },
        {
            "x": -2,
            "y": 11,
            "z": 4,
            
            "elements": [
                "modularmachinery:blockcasing@4"
            ]
        },
        {
            "x": -2,
            "y": 9,
            "z": 3,
            
            "elements": [
                "modularmachinery:blockcasing@0"
            ]
        },
        {
            "x": -2,
            "y": 7,
            "z": 2,
            
            "elements": [
                "modularmachinery:blockcasing@0"
            ]
        },
        {
            "x": 0,
            "y": 11,
            "z": 4,
            
            "elements": [
                "modularmachinery:blockcasing@0"
            ]
        },
        {
            "x": -1,
            "y": 7,
            "z": 2,
            "elements": [
                "projecte:matter_block@0"
            ]
        },
        {
            "x": 0,
            "y": 9,
            "z": 3,
            "elements": [
                "projecte:matter_block@0"
            ]
        },
        {
            "x": 2,
            "y": 11,
            "z": 4,
            
            "elements": [
                "modularmachinery:blockcasing@4"
            ]
        },
        {
            "x": -1,
            "y": 5,
            "z": 1,
            
            "elements": [
                "modularmachinery:blockcasing@4"
            ]
        },
        {
            "x": -2,
            "y": 3,
            "z": 0,
            
            "elements": [
                "modularmachinery:blockcasing@0"
            ]
        },
        {
            "x": 2,
            "y": 9,
            "z": 3,
            
            "elements": [
                "modularmachinery:blockcasing@0"
            ]
        },
        {
            "x": -1,
            "y": 3,
            "z": 0,
            
            "elements": [
                "modularmachinery:blockcasing@4"
            ]
        },
        {
            "x": 1,
            "y": 7,
            "z": 2,
            "elements": [
                "projecte:matter_block@0"
            ]
        },
        {
            "x": 2,
            "y": 7,
            "z": 2,
            
            "elements": [
                "modularmachinery:blockcasing@0"
            ]
        },
        {
            "x": 1,
            "y": 5,
            "z": 1,
            
            "elements": [
                "modularmachinery:blockcasing@4"
            ]
        },
        {
            "x": 0,
            "y": 3,
            "z": 0,
            "elements": [
                "projecte:matter_block@0"
            ]
        },
        {
            "x": 1,
            "y": 3,
            "z": 0,
            
            "elements": [
                "modularmachinery:blockcasing@4"
            ]
        },
        {
            "x": 2,
            "y": 3,
            "z": 0,
            
            "elements": [
                "modularmachinery:blockcasing@0"
            ]
        },
        {
            "x": -3,
            "y": 12,
            "z": 4,
            
            "elements": [
                "modularmachinery:blockcasing@0"
            ]
        },
        {
            "x": -2,
            "y": 12,
            "z": 4,
            
            "elements": [
                "modularmachinery:blockcasing@0"
            ]
        },
        {
            "x": -2,
            "y": 10,
            "z": 3,
            
            "elements": [
                "modularmachinery:blockcasing@0"
            ]
        },
        {
            "x": -2,
            "y": 8,
            "z": 2,
            
            "elements": [
                "modularmachinery:blockcasing@0"
            ]
        },
        {
            "x": 0,
            "y": 12,
            "z": 4,
            
            "elements": [
                "modularmachinery:blockcasing@0"
            ]
        },
        {
            "x": -1,
            "y": 8,
            "z": 2,
            "elements": [
                "chisel:antiblock@15"
            ]
        },
        {
            "x": 0,
            "y": 10,
            "z": 3,
            "elements": [
                "chisel:antiblock@15"
            ]
        },
        {
            "x": 2,
            "y": 12,
            "z": 4,
            
            "elements": [
                "modularmachinery:blockcasing@0"
            ]
        },
        {
            "x": -2,
            "y": 4,
            "z": 0,
            
            "elements": [
                "modularmachinery:blockcasing@0"
            ]
        },
        {
            "x": -1,
            "y": 6,
            "z": 1,
            "elements": [
                "projecte:matter_block@0"
            ]
        },
        {
            "x": 2,
            "y": 10,
            "z": 3,
            
            "elements": [
                "modularmachinery:blockcasing@0"
            ]
        },
        {
            "x": 3,
            "y": 12,
            "z": 4,
            
            "elements": [
                "modularmachinery:blockcasing@0"
            ]
        },
        {
            "x": 0,
            "y": 6,
            "z": 1,
            "elements": [
                "projecte:matter_block@0"
            ]
        },
        {
            "x": 1,
            "y": 8,
            "z": 2,
            "elements": [
                "chisel:antiblock@15"
            ]
        },
        {
            "x": -1,
            "y": 4,
            "z": 0,
            
            "elements": [
                "modularmachinery:blockcasing@0"
            ]
        },
        {
            "x": 2,
            "y": 8,
            "z": 2,
            
            "elements": [
                "modularmachinery:blockcasing@0"
            ]
        },
        {
            "x": 1,
            "y": 6,
            "z": 1,
            "elements": [
                "projecte:matter_block@0"
            ]
        },
        {
            "x": 0,
            "y": 4,
            "z": 0,
            
            "elements": [
                "modularmachinery:blockcasing@4"
            ]
        },
        {
            "x": 1,
            "y": 4,
            "z": 0,
            
            "elements": [
                "modularmachinery:blockcasing@0"
            ]
        },
        {
            "x": 2,
            "y": 4,
            "z": 0,
            
            "elements": [
                "modularmachinery:blockcasing@0"
            ]
        },
        {
            "x": -4,
            "y": 13,
            "z": 4,
            
            "elements": [
                "modularmachinery:blockcasing@0"
            ]
        },
        {
            "x": -3,
            "y": 13,
            "z": 4,
            
            "elements": [
                "modularmachinery:blockcasing@0"
            ]
        },
        {
            "x": -1,
            "y": 11,
            "z": 3,
            "elements": [
                "projecte:matter_block@0"
            ]
        },
        {
            "x": 0,
            "y": 13,
            "z": 4,
            
            "elements": [
                "modularmachinery:blockcasing@0"
            ]
        },
        {
            "x": -1,
            "y": 9,
            "z": 2,
            "elements": [
                "projecte:matter_block@0"
            ]
        },
        {
            "x": 0,
            "y": 11,
            "z": 3,
            "elements": [
                "projecte:matter_block@0"
            ]
        },
        {
            "x": 1,
            "y": 11,
            "z": 3,
            "elements": [
                "projecte:matter_block@0"
            ]
        },
        {
            "x": -2,
            "y": 5,
            "z": 0,
            
            "elements": [
                "modularmachinery:blockcasing@0"
            ]
        },
        {
            "x": -1,
            "y": 7,
            "z": 1,
            "elements": [
                "projecte:matter_block@0"
            ]
        },
        {
            "x": 1,
            "y": 9,
            "z": 2,
            "elements": [
                "projecte:matter_block@0"
            ]
        },
        {
            "x": 0,
            "y": 7,
            "z": 1,
            "elements": [
                "projecte:matter_block@0"
            ]
        },
        {
            "x": 3,
            "y": 13,
            "z": 4,
            
            "elements": [
                "modularmachinery:blockcasing@0"
            ]
        },
        {
            "x": 1,
            "y": 7,
            "z": 1,
            "elements": [
                "projecte:matter_block@0"
            ]
        },
        {
            "x": 4,
            "y": 13,
            "z": 4,
            
            "elements": [
                "modularmachinery:blockcasing@0"
            ]
        },
        {
            "x": 0,
            "y": 5,
            "z": 0,
            
            "elements": [
                "modularmachinery:blockcasing@4"
            ]
        },
        {
            "x": 2,
            "y": 5,
            "z": 0,
            
            "elements": [
                "modularmachinery:blockcasing@0"
            ]
        },
        {
            "x": -4,
            "y": 14,
            "z": 4,
            
            "elements": [
                "modularmachinery:blockcasing@0"
            ]
        },
        {
            "x": -2,
            "y": 10,
            "z": 2,
            
            "elements": [
                "modularmachinery:blockcasing@0"
            ]
        },
        {
            "x": -1,
            "y": 12,
            "z": 3,
            "elements": [
                "projecte:matter_block@0"
            ]
        },
        {
            "x": 0,
            "y": 14,
            "z": 4,
            
            "elements": [
                "modularmachinery:blockcasing@4"
            ]
        },
        {
            "x": -1,
            "y": 10,
            "z": 2,
            "elements": [
                "chisel:antiblock@15"
            ]
        },
        {
            "x": -2,
            "y": 8,
            "z": 1,
            
            "elements": [
                "modularmachinery:blockcasing@0"
            ]
        },
        {
            "x": 1,
            "y": 12,
            "z": 3,
            "elements": [
                "projecte:matter_block@0"
            ]
        },
        {
            "x": -2,
            "y": 6,
            "z": 0,
            
            "elements": [
                "modularmachinery:blockcasing@4"
            ]
        },
        {
            "x": 0,
            "y": 8,
            "z": 1,
            "elements": [
                "chisel:antiblock@15"
            ]
        },
        {
            "x": 1,
            "y": 10,
            "z": 2,
            "elements": [
                "chisel:antiblock@15"
            ]
        },
        {
            "x": 2,
            "y": 10,
            "z": 2,
            
            "elements": [
                "modularmachinery:blockcasing@0"
            ]
        },
        {
            "x": 0,
            "y": 6,
            "z": 0,
            
            "elements": [
                "modularmachinery:blockcasing@0"
            ]
        },
        {
            "x": 4,
            "y": 14,
            "z": 4,
            
            "elements": [
                "modularmachinery:blockcasing@0"
            ]
        },
        {
            "x": 2,
            "y": 8,
            "z": 1,
            
            "elements": [
                "modularmachinery:blockcasing@0"
            ]
        },
        {
            "x": 2,
            "y": 6,
            "z": 0,
            
            "elements": [
                "modularmachinery:blockcasing@4"
            ]
        },
        {
            "x": -6,
            "y": 15,
            "z": 4,
            
            "elements": [
                "modularmachinery:blockcasing@4"
            ]
        },
        {
            "x": -5,
            "y": 15,
            "z": 4,
            
            "elements": [
                "modularmachinery:blockcasing@0"
            ]
        },
        {
            "x": -4,
            "y": 15,
            "z": 4,
            
            "elements": [
                "modularmachinery:blockcasing@0"
            ]
        },
        {
            "x": -3,
            "y": 13,
            "z": 3,
            "elements": [
                "projecte:matter_block@0"
            ]
        },
        {
            "x": -4,
            "y": 11,
            "z": 2,
            
            "elements": [
                "modularmachinery:blockcasing@4"
            ]
        },
        {
            "x": -2,
            "y": 13,
            "z": 3,
            "elements": [
                "projecte:matter_block@0"
            ]
        },
        {
            "x": -3,
            "y": 11,
            "z": 2,
            
            "elements": [
                "modularmachinery:blockcasing@4"
            ]
        },
        {
            "x": -2,
            "y": 11,
            "z": 2,
            
            "elements": [
                "modularmachinery:blockcasing@0"
            ]
        },
        {
            "x": -1,
            "y": 13,
            "z": 3,
            "elements": [
                "projecte:matter_block@0"
            ]
        },
        {
            "x": 0,
            "y": 15,
            "z": 4,
            
            "elements": [
                "modularmachinery:blockcasing@4"
            ]
        },
        {
            "x": -1,
            "y": 11,
            "z": 2,
            "elements": [
                "projecte:matter_block@0"
            ]
        },
        {
            "x": -2,
            "y": 9,
            "z": 1,
            
            "elements": [
                "modularmachinery:blockcasing@0"
            ]
        },
        {
            "x": -2,
            "y": 7,
            "z": 0,
            
            "elements": [
                "modularmachinery:blockcasing@0"
            ]
        },
        {
            "x": 1,
            "y": 13,
            "z": 3,
            "elements": [
                "projecte:matter_block@0"
            ]
        },
        {
            "x": 2,
            "y": 13,
            "z": 3,
            "elements": [
                "projecte:matter_block@0"
            ]
        },
        {
            "x": 0,
            "y": 9,
            "z": 1,
            "elements": [
                "projecte:matter_block@0"
            ]
        },
        {
            "x": 1,
            "y": 11,
            "z": 2,
            "elements": [
                "projecte:matter_block@0"
            ]
        },
        {
            "x": 2,
            "y": 11,
            "z": 2,
            
            "elements": [
                "modularmachinery:blockcasing@0"
            ]
        },
        {
            "x": 3,
            "y": 13,
            "z": 3,
            "elements": [
                "projecte:matter_block@0"
            ]
        },
        {
            "x": 0,
            "y": 7,
            "z": 0,
            
            "elements": [
                "modularmachinery:blockcasing@0"
            ]
        },
        {
            "x": 4,
            "y": 15,
            "z": 4,
            
            "elements": [
                "modularmachinery:blockcasing@0"
            ]
        },
        {
            "x": 2,
            "y": 9,
            "z": 1,
            
            "elements": [
                "modularmachinery:blockcasing@0"
            ]
        },
        {
            "x": 3,
            "y": 11,
            "z": 2,
            
            "elements": [
                "modularmachinery:blockcasing@4"
            ]
        },
        {
            "x": 5,
            "y": 15,
            "z": 4,
            
            "elements": [
                "modularmachinery:blockcasing@0"
            ]
        },
        {
            "x": 2,
            "y": 7,
            "z": 0,
            
            "elements": [
                "modularmachinery:blockcasing@0"
            ]
        },
        {
            "x": 4,
            "y": 11,
            "z": 2,
            
            "elements": [
                "modularmachinery:blockcasing@4"
            ]
        },
        {
            "x": 6,
            "y": 15,
            "z": 4,
            
            "elements": [
                "modularmachinery:blockcasing@4"
            ]
        },
        {
            "x": -5,
            "y": 12,
            "z": 2,
            
            "elements": [
                "modularmachinery:blockcasing@0"
            ]
        },
        {
            "x": -4,
            "y": 14,
            "z": 3,
            "elements": [
                "projecte:matter_block@0"
            ]
        },
        {
            "x": -4,
            "y": 12,
            "z": 2,
            
            "elements": [
                "modularmachinery:blockcasing@0"
            ]
        },
        {
            "x": -3,
            "y": 14,
            "z": 3,
            "elements": [
                "projecte:matter_block@0"
            ]
        },
        {
            "x": -2,
            "y": 14,
            "z": 3,
            "elements": [
                "projecte:matter_block@0"
            ]
        },
        {
            "x": -1,
            "y": 16,
            "z": 4,
            "elements": [
                "projecte:matter_block@0"
            ]
        },
        {
            "x": -1,
            "y": 14,
            "z": 3,
            "elements": [
                "projecte:matter_block@0"
            ]
        },
        {
            "x": 0,
            "y": 16,
            "z": 4,
            
            "elements": [
                "modularmachinery:blockcasing@0"
            ]
        },
        {
            "x": -2,
            "y": 10,
            "z": 1,
            
            "elements": [
                "modularmachinery:blockcasing@0"
            ]
        },
        {
            "x": -1,
            "y": 12,
            "z": 2,
            "elements": [
                "projecte:matter_block@0"
            ]
        },
        {
            "x": 1,
            "y": 16,
            "z": 4,
            "elements": [
                "projecte:matter_block@0"
            ]
        },
        {
            "x": 0,
            "y": 12,
            "z": 2,
            "elements": [
                "projecte:matter_block@0"
            ]
        },
        {
            "x": -2,
            "y": 8,
            "z": 0,
            
            "elements": [
                "modularmachinery:blockcasing@4"
            ]
        },
        {
            "x": 1,
            "y": 14,
            "z": 3,
            "elements": [
                "projecte:matter_block@0"
            ]
        },
        {
            "x": 1,
            "y": 12,
            "z": 2,
            "elements": [
                "projecte:matter_block@0"
            ]
        },
        {
            "x": 0,
            "y": 10,
            "z": 1,
            "elements": [
                "chisel:antiblock@15"
            ]
        },
        {
            "x": -1,
            "y": 8,
            "z": 0,
            
            "elements": [
                "modularmachinery:blockcasing@0"
            ]
        },
        {
            "x": 2,
            "y": 14,
            "z": 3,
            "elements": [
                "projecte:matter_block@0"
            ]
        },
        {
            "x": 0,
            "y": 8,
            "z": 0,
            
            "elements": [
                "modularmachinery:blockcasing@0"
            ]
        },
        {
            "x": 3,
            "y": 14,
            "z": 3,
            "elements": [
                "projecte:matter_block@0"
            ]
        },
        {
            "x": 2,
            "y": 10,
            "z": 1,
            
            "elements": [
                "modularmachinery:blockcasing@0"
            ]
        },
        {
            "x": 1,
            "y": 8,
            "z": 0,
            
            "elements": [
                "modularmachinery:blockcasing@0"
            ]
        },
        {
            "x": 4,
            "y": 14,
            "z": 3,
            "elements": [
                "projecte:matter_block@0"
            ]
        },
        {
            "x": 2,
            "y": 8,
            "z": 0,
            
            "elements": [
                "modularmachinery:blockcasing@4"
            ]
        },
        {
            "x": 4,
            "y": 12,
            "z": 2,
            
            "elements": [
                "modularmachinery:blockcasing@0"
            ]
        },
        {
            "x": 5,
            "y": 12,
            "z": 2,
            
            "elements": [
                "modularmachinery:blockcasing@0"
            ]
        },
        {
            "x": -6,
            "y": 15,
            "z": 3,
            
            "elements": [
                "modularmachinery:blockcasing@0"
            ]
        },
        {
            "x": -6,
            "y": 13,
            "z": 2,
            
            "elements": [
                "modularmachinery:blockcasing@0"
            ]
        },
        {
            "x": -5,
            "y": 13,
            "z": 2,
            
            "elements": [
                "modularmachinery:blockcasing@4"
            ]
        },
        {
            "x": -4,
            "y": 15,
            "z": 3,
            "elements": [
                "projecte:matter_block@0"
            ]
        },
        {
            "x": -3,
            "y": 15,
            "z": 3,
            "elements": [
                "projecte:matter_block@0"
            ]
        },
        {
            "x": -3,
            "y": 13,
            "z": 2,
            "elements": [
                "projecte:matter_block@0"
            ]
        },
        {
            "x": -2,
            "y": 15,
            "z": 3,
            "elements": [
                "projecte:matter_block@0"
            ]
        },
        {
            "x": -1,
            "y": 17,
            "z": 4,
            "elements": [
                "projecte:matter_block@0"
            ]
        },
        {
            "x": -2,
            "y": 13,
            "z": 2,
            "elements": [
                "projecte:matter_block@0"
            ]
        },
        {
            "x": -1,
            "y": 15,
            "z": 3,
            "elements": [
                "projecte:matter_block@0"
            ]
        },
        {
            "x": 0,
            "y": 17,
            "z": 4,
            
            "elements": [
                "modularmachinery:blockcasing@0"
            ]
        },
        {
            "x": -1,
            "y": 13,
            "z": 2,
            "elements": [
                "chisel:antiblock@7"
            ]
        },
        {
            "x": 1,
            "y": 17,
            "z": 4,
            "elements": [
                "projecte:matter_block@0"
            ]
        },
        {
            "x": -2,
            "y": 9,
            "z": 0,
            "elements": [
                "projecte:matter_block@0"
            ]
        },
        {
            "x": -1,
            "y": 11,
            "z": 1,
            "elements": [
                "projecte:matter_block@0"
            ]
        },
        {
            "x": 0,
            "y": 13,
            "z": 2,
            "elements": [
                "projectex:relay@4"
            ]
        },
        {
            "x": 1,
            "y": 15,
            "z": 3,
            "elements": [
                "projecte:matter_block@0"
            ]
        },
        {
            "x": 0,
            "y": 11,
            "z": 1,
            "elements": [
                "projecte:matter_block@0"
            ]
        },
        {
            "x": -1,
            "y": 9,
            "z": 0,
            
            "elements": [
                "modularmachinery:blockcasing@0"
            ]
        },
        {
            "x": 1,
            "y": 13,
            "z": 2,
            "elements": [
                "chisel:antiblock@7"
            ]
        },
        {
            "x": 2,
            "y": 15,
            "z": 3,
            "elements": [
                "projecte:matter_block@0"
            ]
        },
        {
            "x": 1,
            "y": 11,
            "z": 1,
            "elements": [
                "projecte:matter_block@0"
            ]
        },
        {
            "x": 2,
            "y": 13,
            "z": 2,
            "elements": [
                "projecte:matter_block@0"
            ]
        },
        {
            "x": 3,
            "y": 15,
            "z": 3,
            "elements": [
                "projecte:matter_block@0"
            ]
        },
        {
            "x": 3,
            "y": 13,
            "z": 2,
            "elements": [
                "projecte:matter_block@0"
            ]
        },
        {
            "x": 1,
            "y": 9,
            "z": 0,
            
            "elements": [
                "modularmachinery:blockcasing@0"
            ]
        },
        {
            "x": 4,
            "y": 15,
            "z": 3,
            "elements": [
                "projecte:matter_block@0"
            ]
        },
        {
            "x": 2,
            "y": 9,
            "z": 0,
            "elements": [
                "projecte:matter_block@0"
            ]
        },
        {
            "x": 5,
            "y": 13,
            "z": 2,
            
            "elements": [
                "modularmachinery:blockcasing@4"
            ]
        },
        {
            "x": 6,
            "y": 15,
            "z": 3,
            
            "elements": [
                "modularmachinery:blockcasing@0"
            ]
        },
        {
            "x": 6,
            "y": 13,
            "z": 2,
            
            "elements": [
                "modularmachinery:blockcasing@0"
            ]
        },
        {
            "x": -6,
            "y": 14,
            "z": 2,
            
            "elements": [
                "modularmachinery:blockcasing@0"
            ]
        },
        {
            "x": -5,
            "y": 16,
            "z": 3,
            "elements": [
                "projecte:matter_block@0"
            ]
        },
        {
            "x": -4,
            "y": 16,
            "z": 3,
            "elements": [
                "projecte:matter_block@0"
            ]
        },
        {
            "x": -4,
            "y": 14,
            "z": 2,
            "elements": [
                "projecte:matter_block@0"
            ]
        },
        {
            "x": -3,
            "y": 16,
            "z": 3,
            "elements": [
                "projecte:matter_block@0"
            ]
        },
        {
            "x": -3,
            "y": 14,
            "z": 2,
            
            "elements": [
                "projectex:relay@4"
            ]
        },
        {
            "x": -2,
            "y": 16,
            "z": 3,
            "elements": [
                "projecte:matter_block@0"
            ]
        },
        {
            "x": -1,
            "y": 18,
            "z": 4,
            "elements": [
                "projecte:matter_block@0"
            ]
        },
        {
            "x": -2,
            "y": 14,
            "z": 2,
            "elements": [
                "chisel:antiblock@7"
            ]
        },
        {
            "x": -1,
            "y": 16,
            "z": 3,
            
            "elements": [
                "projectex:relay@4"
            ]
        },
        {
            "x": 0,
            "y": 18,
            "z": 4,
            
            "elements": [
                "modularmachinery:blockcasing@0"
            ]
        },
        {
            "x": -1,
            "y": 14,
            "z": 2,
            "elements": [
                "chisel:antiblock@15"
            ]
        },
        {
            "x": 0,
            "y": 16,
            "z": 3,
            
            "elements": [
                "projectex:relay@4"
            ]
        },
        {
            "x": 1,
            "y": 18,
            "z": 4,
            "elements": [
                "projecte:matter_block@0"
            ]
        },
        {
            "x": -2,
            "y": 10,
            "z": 0,
            "elements": [
                "projecte:matter_block@0"
            ]
        },
        {
            "x": -1,
            "y": 12,
            "z": 1,
            "elements": [
                "projecte:matter_block@0"
            ]
        },
        {
            "x": 0,
            "y": 14,
            "z": 2,
            "elements": [
                "projecte:matter_block@0"
            ]
        },
        {
            "x": 1,
            "y": 16,
            "z": 3,
            
            "elements": [
                "projectex:relay@4"
            ]
        },
        {
            "x": -1,
            "y": 10,
            "z": 0,
            
            "elements": [
                "modularmachinery:blockcasing@0"
            ]
        },
        {
            "x": 0,
            "y": 12,
            "z": 1,
            "elements": [
                "projecte:matter_block@0"
            ]
        },
        {
            "x": 1,
            "y": 14,
            "z": 2,
            "elements": [
                "chisel:antiblock@15"
            ]
        },
        {
            "x": 2,
            "y": 16,
            "z": 3,
            "elements": [
                "projecte:matter_block@0"
            ]
        },
        {
            "x": 0,
            "y": 10,
            "z": 0,
            
            "elements": [
                "modularmachinery:blockcasing@0"
            ]
        },
        {
            "x": 1,
            "y": 12,
            "z": 1,
            "elements": [
                "projecte:matter_block@0"
            ]
        },
        {
            "x": 2,
            "y": 14,
            "z": 2,
            "elements": [
                "chisel:antiblock@7"
            ]
        },
        {
            "x": 3,
            "y": 16,
            "z": 3,
            "elements": [
                "projecte:matter_block@0"
            ]
        },
        {
            "x": 1,
            "y": 10,
            "z": 0,
            
            "elements": [
                "modularmachinery:blockcasing@0"
            ]
        },
        {
            "x": 3,
            "y": 14,
            "z": 2,
            
            "elements": [
                "projectex:relay@4"
            ]
        },
        {
            "x": 4,
            "y": 16,
            "z": 3,
            "elements": [
                "projecte:matter_block@0"
            ]
        },
        {
            "x": 2,
            "y": 10,
            "z": 0,
            "elements": [
                "projecte:matter_block@0"
            ]
        },
        {
            "x": 4,
            "y": 14,
            "z": 2,
            "elements": [
                "projecte:matter_block@0"
            ]
        },
        {
            "x": 5,
            "y": 16,
            "z": 3,
            "elements": [
                "projecte:matter_block@0"
            ]
        },
        {
            "x": 6,
            "y": 14,
            "z": 2,
            
            "elements": [
                "modularmachinery:blockcasing@0"
            ]
        },
        {
            "x": -6,
            "y": 19,
            "z": 4,
            
            "elements": [
                "modularmachinery:blockcasing@4"
            ]
        },
        {
            "x": -5,
            "y": 19,
            "z": 4,
            
            "elements": [
                "modularmachinery:blockcasing@0"
            ]
        },
        {
            "x": -6,
            "y": 15,
            "z": 2,
            
            "elements": [
                "modularmachinery:blockcasing@0"
            ]
        },
        {
            "x": -5,
            "y": 17,
            "z": 3,
            "elements": [
                "projecte:matter_block@0"
            ]
        },
        {
            "x": -4,
            "y": 19,
            "z": 4,
            
            "elements": [
                "modularmachinery:blockcasing@0"
            ]
        },
        {
            "x": -4,
            "y": 17,
            "z": 3,
            "elements": [
                "projecte:matter_block@0"
            ]
        },
        {
            "x": -4,
            "y": 15,
            "z": 2,
            "elements": [
                "projecte:matter_block@0"
            ]
        },
        {
            "x": -3,
            "y": 17,
            "z": 3,
            "elements": [
                "projecte:matter_block@0"
            ]
        },
        {
            "x": -3,
            "y": 15,
            "z": 2,
            "elements": [
                "chisel:antiblock@7"
            ]
        },
        {
            "x": -2,
            "y": 17,
            "z": 3,
            "elements": [
                "projecte:matter_block@0"
            ]
        },
        {
            "x": -3,
            "y": 13,
            "z": 1,
            "elements": [
                "projecte:matter_block@0"
            ]
        },
        {
            "x": 0,
            "y": 19,
            "z": 4,
            
            "elements": [
                "modularmachinery:blockcasing@4"
            ]
        },
        {
            "x": -2,
            "y": 15,
            "z": 2,
            "elements": [
                "chisel:antiblock@15"
            ]
        },
        {
            "x": -1,
            "y": 17,
            "z": 3,
            
            "elements": [
                "projectex:relay@4"
            ]
        },
        {
            "x": -2,
            "y": 13,
            "z": 1,
            "elements": [
                "projecte:matter_block@0"
            ]
        },
        {
            "x": -1,
            "y": 15,
            "z": 2,
            "elements": [
                "chisel:antiblock@15"
            ]
        },
        {
            "x": 0,
            "y": 17,
            "z": 3,
            
            "elements": [
                "projectex:relay@4"
            ]
        },
        {
            "x": -2,
            "y": 11,
            "z": 0,
            
            "elements": [
                "modularmachinery:blockcasing@4"
            ]
        },
        {
            "x": 0,
            "y": 15,
            "z": 2,
            "elements": [
                "projecte:matter_block@0"
            ]
        },
        {
            "x": 1,
            "y": 17,
            "z": 3,
            
            "elements": [
                "projectex:relay@4"
            ]
        },
        {
            "x": 1,
            "y": 15,
            "z": 2,
            "elements": [
                "chisel:antiblock@15"
            ]
        },
        {
            "x": 2,
            "y": 17,
            "z": 3,
            "elements": [
                "projecte:matter_block@0"
            ]
        },
        {
            "x": 4,
            "y": 19,
            "z": 4,
            
            "elements": [
                "modularmachinery:blockcasing@0"
            ]
        },
        {
            "x": 2,
            "y": 15,
            "z": 2,
            "elements": [
                "chisel:antiblock@15"
            ]
        },
        {
            "x": 3,
            "y": 17,
            "z": 3,
            "elements": [
                "projecte:matter_block@0"
            ]
        },
        {
            "x": 2,
            "y": 13,
            "z": 1,
            "elements": [
                "projecte:matter_block@0"
            ]
        },
        {
            "x": 5,
            "y": 19,
            "z": 4,
            
            "elements": [
                "modularmachinery:blockcasing@0"
            ]
        },
        {
            "x": 3,
            "y": 15,
            "z": 2,
            "elements": [
                "chisel:antiblock@7"
            ]
        },
        {
            "x": 4,
            "y": 17,
            "z": 3,
            "elements": [
                "projecte:matter_block@0"
            ]
        },
        {
            "x": 2,
            "y": 11,
            "z": 0,
            
            "elements": [
                "modularmachinery:blockcasing@4"
            ]
        },
        {
            "x": 4,
            "y": 15,
            "z": 2,
            "elements": [
                "projecte:matter_block@0"
            ]
        },
        {
            "x": 3,
            "y": 13,
            "z": 1,
            "elements": [
                "projecte:matter_block@0"
            ]
        },
        {
            "x": 6,
            "y": 19,
            "z": 4,
            
            "elements": [
                "modularmachinery:blockcasing@4"
            ]
        },
        {
            "x": 5,
            "y": 17,
            "z": 3,
            "elements": [
                "projecte:matter_block@0"
            ]
        },
        {
            "x": 6,
            "y": 15,
            "z": 2,
            
            "elements": [
                "modularmachinery:blockcasing@0"
            ]
        },
        {
            "x": -5,
            "y": 18,
            "z": 3,
            "elements": [
                "projecte:matter_block@0"
            ]
        },
        {
            "x": -6,
            "y": 16,
            "z": 2,
            
            "elements": [
                "modularmachinery:blockcasing@0"
            ]
        },
        {
            "x": -4,
            "y": 20,
            "z": 4,
            
            "elements": [
                "modularmachinery:blockcasing@4"
            ]
        },
        {
            "x": -5,
            "y": 16,
            "z": 2,
            "elements": [
                "projecte:matter_block@0"
            ]
        },
        {
            "x": -4,
            "y": 18,
            "z": 3,
            "elements": [
                "projecte:matter_block@0"
            ]
        },
        {
            "x": -4,
            "y": 16,
            "z": 2,
            "elements": [
                "chisel:antiblock@7"
            ]
        },
        {
            "x": -3,
            "y": 18,
            "z": 3,
            "elements": [
                "projecte:matter_block@0"
            ]
        },
        {
            "x": -4,
            "y": 14,
            "z": 1,
            "elements": [
                "projecte:matter_block@0"
            ]
        },
        {
            "x": -3,
            "y": 16,
            "z": 2,
            "elements": [
                "chisel:antiblock@15"
            ]
        },
        {
            "x": -2,
            "y": 18,
            "z": 3,
            "elements": [
                "projecte:matter_block@0"
            ]
        },
        {
            "x": 0,
            "y": 20,
            "z": 4,
            
            "elements": [
                "modularmachinery:blockcasing@4"
            ]
        },
        {
            "x": -2,
            "y": 16,
            "z": 2,
            "elements": [
                "chisel:antiblock@15"
            ]
        },
        {
            "x": -1,
            "y": 18,
            "z": 3,
            
            "elements": [
                "projectex:relay@4"
            ]
        },
        {
            "x": -3,
            "y": 12,
            "z": 0,
            
            "elements": [
                "modularmachinery:blockcasing@0"
            ]
        },
        {
            "x": 0,
            "y": 18,
            "z": 3,
            
            "elements": [
                "projectex:relay@4"
            ]
        },
        {
            "x": -2,
            "y": 12,
            "z": 0,
            
            "elements": [
                "modularmachinery:blockcasing@0"
            ]
        },
        {
            "x": 0,
            "y": 16,
            "z": 2,
            "elements": [
                "projecte:matter_block@0"
            ]
        },
        {
            "x": 1,
            "y": 18,
            "z": 3,
            
            "elements": [
                "projectex:relay@4"
            ]
        },
        {
            "x": -1,
            "y": 12,
            "z": 0,
            
            "elements": [
                "modularmachinery:blockcasing@0"
            ]
        },
        {
            "x": 1,
            "y": 16,
            "z": 2,
            "elements": [
                "chisel:antiblock@15"
            ]
        },
        {
            "x": 2,
            "y": 18,
            "z": 3,
            "elements": [
                "projecte:matter_block@0"
            ]
        },
        {
            "x": 0,
            "y": 12,
            "z": 0,
            
            "elements": [
                "modularmachinery:blockcasing@4"
            ]
        },
        {
            "x": 4,
            "y": 20,
            "z": 4,
            
            "elements": [
                "modularmachinery:blockcasing@4"
            ]
        },
        {
            "x": 2,
            "y": 16,
            "z": 2,
            "elements": [
                "chisel:antiblock@15"
            ]
        },
        {
            "x": 3,
            "y": 18,
            "z": 3,
            "elements": [
                "projecte:matter_block@0"
            ]
        },
        {
            "x": 1,
            "y": 12,
            "z": 0,
            
            "elements": [
                "modularmachinery:blockcasing@0"
            ]
        },
        {
            "x": 3,
            "y": 16,
            "z": 2,
            "elements": [
                "chisel:antiblock@15"
            ]
        },
        {
            "x": 4,
            "y": 18,
            "z": 3,
            "elements": [
                "projecte:matter_block@0"
            ]
        },
        {
            "x": 2,
            "y": 12,
            "z": 0,
            
            "elements": [
                "modularmachinery:blockcasing@0"
            ]
        },
        {
            "x": 4,
            "y": 16,
            "z": 2,
            "elements": [
                "chisel:antiblock@7"
            ]
        },
        {
            "x": 5,
            "y": 18,
            "z": 3,
            "elements": [
                "projecte:matter_block@0"
            ]
        },
        {
            "x": 3,
            "y": 12,
            "z": 0,
            
            "elements": [
                "modularmachinery:blockcasing@0"
            ]
        },
        {
            "x": 5,
            "y": 16,
            "z": 2,
            "elements": [
                "projecte:matter_block@0"
            ]
        },
        {
            "x": 4,
            "y": 14,
            "z": 1,
            "elements": [
                "projecte:matter_block@0"
            ]
        },
        {
            "x": 6,
            "y": 16,
            "z": 2,
            
            "elements": [
                "modularmachinery:blockcasing@0"
            ]
        },
        {
            "x": -6,
            "y": 19,
            "z": 3,
            
            "elements": [
                "modularmachinery:blockcasing@0"
            ]
        },
        {
            "x": -6,
            "y": 17,
            "z": 2,
            
            "elements": [
                "modularmachinery:blockcasing@4"
            ]
        },
        {
            "x": -4,
            "y": 21,
            "z": 4,
            
            "elements": [
                "modularmachinery:blockcasing@0"
            ]
        },
        {
            "x": -6,
            "y": 15,
            "z": 1,
            
            "elements": [
                "modularmachinery:blockcasing@0"
            ]
        },
        {
            "x": -4,
            "y": 19,
            "z": 3,
            "elements": [
                "projecte:matter_block@0"
            ]
        },
        {
            "x": -4,
            "y": 17,
            "z": 2,
            
            "elements": [
                "projectex:relay@4"
            ]
        },
        {
            "x": -3,
            "y": 19,
            "z": 3,
            "elements": [
                "projecte:matter_block@0"
            ]
        },
        {
            "x": -4,
            "y": 15,
            "z": 1,
            "elements": [
                "projecte:matter_block@0"
            ]
        },
        {
            "x": -3,
            "y": 17,
            "z": 2,
            "elements": [
                "projecte:matter_block@0"
            ]
        },
        {
            "x": -2,
            "y": 19,
            "z": 3,
            "elements": [
                "projecte:matter_block@0"
            ]
        },
        {
            "x": -4,
            "y": 13,
            "z": 0,
            
            "elements": [
                "modularmachinery:blockcasing@0"
            ]
        },
        {
            "x": 0,
            "y": 21,
            "z": 4,
            
            "elements": [
                "modularmachinery:blockcasing@0"
            ]
        },
        {
            "x": -2,
            "y": 17,
            "z": 2,
            "elements": [
                "projecte:matter_block@0"
            ]
        },
        {
            "x": -1,
            "y": 19,
            "z": 3,
            "elements": [
                "projecte:matter_block@0"
            ]
        },
        {
            "x": -1,
            "y": 17,
            "z": 2,
            "elements": [
                "projecte:matter_block@0"
            ]
        },
        {
            "x": 0,
            "y": 17,
            "z": 2,
            "elements": [
                "projecte:matter_block@0"
            ]
        },
        {
            "x": 1,
            "y": 19,
            "z": 3,
            "elements": [
                "projecte:matter_block@0"
            ]
        },
        {
            "x": 1,
            "y": 17,
            "z": 2,
            "elements": [
                "chisel:antiblock@15"
            ]
        },
        {
            "x": 2,
            "y": 19,
            "z": 3,
            "elements": [
                "projecte:matter_block@0"
            ]
        },
        {
            "x": 4,
            "y": 21,
            "z": 4,
            
            "elements": [
                "modularmachinery:blockcasing@0"
            ]
        },
        {
            "x": 2,
            "y": 17,
            "z": 2,
            "elements": [
                "chisel:antiblock@15"
            ]
        },
        {
            "x": 3,
            "y": 19,
            "z": 3,
            "elements": [
                "projecte:matter_block@0"
            ]
        },
        {
            "x": 3,
            "y": 17,
            "z": 2,
            "elements": [
                "chisel:antiblock@15"
            ]
        },
        {
            "x": 4,
            "y": 19,
            "z": 3,
            "elements": [
                "projecte:matter_block@0"
            ]
        },
        {
            "x": 4,
            "y": 17,
            "z": 2,
            
            "elements": [
                "projectex:relay@4"
            ]
        },
        {
            "x": 4,
            "y": 15,
            "z": 1,
            "elements": [
                "projecte:matter_block@0"
            ]
        },
        {
            "x": 6,
            "y": 19,
            "z": 3,
            
            "elements": [
                "modularmachinery:blockcasing@0"
            ]
        },
        {
            "x": 4,
            "y": 13,
            "z": 0,
            
            "elements": [
                "modularmachinery:blockcasing@0"
            ]
        },
        {
            "x": 6,
            "y": 17,
            "z": 2,
            
            "elements": [
                "modularmachinery:blockcasing@4"
            ]
        },
        {
            "x": 6,
            "y": 15,
            "z": 1,
            
            "elements": [
                "modularmachinery:blockcasing@0"
            ]
        },
        {
            "x": -6,
            "y": 18,
            "z": 2,
            
            "elements": [
                "modularmachinery:blockcasing@0"
            ]
        },
        {
            "x": -3,
            "y": 22,
            "z": 4,
            
            "elements": [
                "modularmachinery:blockcasing@0"
            ]
        },
        {
            "x": -4,
            "y": 20,
            "z": 3,
            "elements": [
                "projecte:matter_block@0"
            ]
        },
        {
            "x": -5,
            "y": 16,
            "z": 1,
            "elements": [
                "projecte:matter_block@0"
            ]
        },
        {
            "x": -4,
            "y": 18,
            "z": 2,
            "elements": [
                "chisel:antiblock@7"
            ]
        },
        {
            "x": -3,
            "y": 20,
            "z": 3,
            "elements": [
                "projecte:matter_block@0"
            ]
        },
        {
            "x": -2,
            "y": 22,
            "z": 4,
            
            "elements": [
                "modularmachinery:blockcasing@0"
            ]
        },
        {
            "x": -3,
            "y": 18,
            "z": 2,
            "elements": [
                "chisel:antiblock@15"
            ]
        },
        {
            "x": -2,
            "y": 20,
            "z": 3,
            "elements": [
                "projecte:matter_block@0"
            ]
        },
        {
            "x": -1,
            "y": 22,
            "z": 4,
            
            "elements": [
                "modularmachinery:blockcasing@0"
            ]
        },
        {
            "x": -4,
            "y": 14,
            "z": 0,
            
            "elements": [
                "modularmachinery:blockcasing@4"
            ]
        },
        {
            "x": 0,
            "y": 22,
            "z": 4,
            
            "elements": [
                "modularmachinery:blockcasing@4"
            ]
        },
        {
            "x": -2,
            "y": 18,
            "z": 2,
            "elements": [
                "chisel:antiblock@15"
            ]
        },
        {
            "x": -1,
            "y": 20,
            "z": 3,
            "elements": [
                "projecte:matter_block@0"
            ]
        },
        {
            "x": 1,
            "y": 22,
            "z": 4,
            
            "elements": [
                "modularmachinery:blockcasing@0"
            ]
        },
        {
            "x": -1,
            "y": 18,
            "z": 2,
            "elements": [
                "chisel:antiblock@15"
            ]
        },
        {
            "x": 2,
            "y": 22,
            "z": 4,
            
            "elements": [
                "modularmachinery:blockcasing@0"
            ]
        },
        {
            "x": 0,
            "y": 18,
            "z": 2,
            "elements": [
                "chisel:antiblock@15"
            ]
        },
        {
            "x": 1,
            "y": 20,
            "z": 3,
            "elements": [
                "projecte:matter_block@0"
            ]
        },
        {
            "x": 3,
            "y": 22,
            "z": 4,
            
            "elements": [
                "modularmachinery:blockcasing@0"
            ]
        },
        {
            "x": 1,
            "y": 18,
            "z": 2,
            "elements": [
                "chisel:antiblock@15"
            ]
        },
        {
            "x": 2,
            "y": 20,
            "z": 3,
            "elements": [
                "projecte:matter_block@0"
            ]
        },
        {
            "x": 2,
            "y": 18,
            "z": 2,
            "elements": [
                "chisel:antiblock@15"
            ]
        },
        {
            "x": 3,
            "y": 20,
            "z": 3,
            "elements": [
                "projecte:matter_block@0"
            ]
        },
        {
            "x": 3,
            "y": 18,
            "z": 2,
            "elements": [
                "chisel:antiblock@15"
            ]
        },
        {
            "x": 4,
            "y": 20,
            "z": 3,
            "elements": [
                "projecte:matter_block@0"
            ]
        },
        {
            "x": 4,
            "y": 18,
            "z": 2,
            "elements": [
                "chisel:antiblock@7"
            ]
        },
        {
            "x": 5,
            "y": 16,
            "z": 1,
            "elements": [
                "projecte:matter_block@0"
            ]
        },
        {
            "x": 4,
            "y": 14,
            "z": 0,
            
            "elements": [
                "modularmachinery:blockcasing@4"
            ]
        },
        {
            "x": 6,
            "y": 18,
            "z": 2,
            
            "elements": [
                "modularmachinery:blockcasing@0"
            ]
        },
        {
            "x": -6,
            "y": 19,
            "z": 2,
            
            "elements": [
                "modularmachinery:blockcasing@4"
            ]
        },
        {
            "x": -5,
            "y": 19,
            "z": 2,
            
            "elements": [
                "modularmachinery:blockcasing@4"
            ]
        },
        {
            "x": -6,
            "y": 15,
            "z": 0,
            
            "elements": [
                "modularmachinery:blockcasing@4"
            ]
        },
        {
            "x": -5,
            "y": 17,
            "z": 1,
            "elements": [
                "projecte:matter_block@0"
            ]
        },
        {
            "x": -3,
            "y": 21,
            "z": 3,
            "elements": [
                "projecte:matter_block@0"
            ]
        },
        {
            "x": -5,
            "y": 15,
            "z": 0,
            
            "elements": [
                "modularmachinery:blockcasing@0"
            ]
        },
        {
            "x": -3,
            "y": 19,
            "z": 2,
            "elements": [
                "chisel:antiblock@7"
            ]
        },
        {
            "x": -2,
            "y": 21,
            "z": 3,
            "elements": [
                "projecte:matter_block@0"
            ]
        },
        {
            "x": -4,
            "y": 15,
            "z": 0,
            
            "elements": [
                "modularmachinery:blockcasing@0"
            ]
        },
        {
            "x": 0,
            "y": 23,
            "z": 4,
            
            "elements": [
                "modularmachinery:blockcasing@0"
            ]
        },
        {
            "x": -2,
            "y": 19,
            "z": 2,
            "elements": [
                "chisel:antiblock@15"
            ]
        },
        {
            "x": -1,
            "y": 21,
            "z": 3,
            "elements": [
                "projecte:matter_block@0"
            ]
        },
        {
            "x": -1,
            "y": 19,
            "z": 2,
            "elements": [
                "chisel:antiblock@15"
            ]
        },
        {
            "x": 0,
            "y": 19,
            "z": 2,
            "elements": [
                "chisel:antiblock@15"
            ]
        },
        {
            "x": 1,
            "y": 21,
            "z": 3,
            "elements": [
                "projecte:matter_block@0"
            ]
        },
        {
            "x": 1,
            "y": 19,
            "z": 2,
            "elements": [
                "chisel:antiblock@15"
            ]
        },
        {
            "x": 2,
            "y": 21,
            "z": 3,
            "elements": [
                "projecte:matter_block@0"
            ]
        },
        {
            "x": 2,
            "y": 19,
            "z": 2,
            "elements": [
                "chisel:antiblock@15"
            ]
        },
        {
            "x": 3,
            "y": 21,
            "z": 3,
            "elements": [
                "projecte:matter_block@0"
            ]
        },
        {
            "x": 3,
            "y": 19,
            "z": 2,
            "elements": [
                "chisel:antiblock@7"
            ]
        },
        {
            "x": 5,
            "y": 19,
            "z": 2,
            
            "elements": [
                "modularmachinery:blockcasing@4"
            ]
        },
        {
            "x": 4,
            "y": 15,
            "z": 0,
            
            "elements": [
                "modularmachinery:blockcasing@0"
            ]
        },
        {
            "x": 6,
            "y": 19,
            "z": 2,
            
            "elements": [
                "modularmachinery:blockcasing@4"
            ]
        },
        {
            "x": 5,
            "y": 17,
            "z": 1,
            "elements": [
                "projecte:matter_block@0"
            ]
        },
        {
            "x": 5,
            "y": 15,
            "z": 0,
            
            "elements": [
                "modularmachinery:blockcasing@0"
            ]
        },
        {
            "x": 6,
            "y": 15,
            "z": 0,
            
            "elements": [
                "modularmachinery:blockcasing@4"
            ]
        },
        {
            "x": -5,
            "y": 20,
            "z": 2,
            
            "elements": [
                "modularmachinery:blockcasing@0"
            ]
        },
        {
            "x": -5,
            "y": 18,
            "z": 1,
            "elements": [
                "projecte:matter_block@0"
            ]
        },
        {
            "x": -3,
            "y": 20,
            "z": 2,
            
            "elements": [
                "projectex:relay@4"
            ]
        },
        {
            "x": -2,
            "y": 20,
            "z": 2,
            "elements": [
                "chisel:antiblock@7"
            ]
        },
        {
            "x": -1,
            "y": 22,
            "z": 3,
            "elements": [
                "projecte:matter_block@0"
            ]
        },
        {
            "x": -1,
            "y": 20,
            "z": 2,
            "elements": [
                "chisel:antiblock@15"
            ]
        },
        {
            "x": 0,
            "y": 20,
            "z": 2,
            "elements": [
                "chisel:antiblock@15"
            ]
        },
        {
            "x": 1,
            "y": 22,
            "z": 3,
            "elements": [
                "projecte:matter_block@0"
            ]
        },
        {
            "x": 1,
            "y": 20,
            "z": 2,
            "elements": [
                "chisel:antiblock@15"
            ]
        },
        {
            "x": 2,
            "y": 20,
            "z": 2,
            "elements": [
                "chisel:antiblock@7"
            ]
        },
        {
            "x": 3,
            "y": 20,
            "z": 2,
            
            "elements": [
                "projectex:relay@4"
            ]
        },
        {
            "x": 5,
            "y": 20,
            "z": 2,
            
            "elements": [
                "modularmachinery:blockcasing@0"
            ]
        },
        {
            "x": 5,
            "y": 18,
            "z": 1,
            "elements": [
                "projecte:matter_block@0"
            ]
        },
        {
            "x": -6,
            "y": 19,
            "z": 1,
            
            "elements": [
                "modularmachinery:blockcasing@0"
            ]
        },
        {
            "x": -5,
            "y": 21,
            "z": 2,
            
            "elements": [
                "modularmachinery:blockcasing@0"
            ]
        },
        {
            "x": -4,
            "y": 21,
            "z": 2,
            
            "elements": [
                "modularmachinery:blockcasing@4"
            ]
        },
        {
            "x": -4,
            "y": 19,
            "z": 1,
            "elements": [
                "projecte:matter_block@0"
            ]
        },
        {
            "x": -1,
            "y": 21,
            "z": 2,
            "elements": [
                "chisel:antiblock@7"
            ]
        },
        {
            "x": 0,
            "y": 23,
            "z": 3,
            
            "elements": [
                "modularmachinery:blockcasing@4"
            ]
        },
        {
            "x": 0,
            "y": 21,
            "z": 2,
            
            "elements": [
                "projectex:relay@4"
            ]
        },
        {
            "x": 1,
            "y": 21,
            "z": 2,
            "elements": [
                "chisel:antiblock@7"
            ]
        },
        {
            "x": 4,
            "y": 21,
            "z": 2,
            
            "elements": [
                "modularmachinery:blockcasing@4"
            ]
        },
        {
            "x": 4,
            "y": 19,
            "z": 1,
            "elements": [
                "projecte:matter_block@0"
            ]
        },
        {
            "x": 5,
            "y": 21,
            "z": 2,
            
            "elements": [
                "modularmachinery:blockcasing@0"
            ]
        },
        {
            "x": 6,
            "y": 19,
            "z": 1,
            
            "elements": [
                "modularmachinery:blockcasing@0"
            ]
        },
        {
            "x": -4,
            "y": 22,
            "z": 2,
            
            "elements": [
                "modularmachinery:blockcasing@0"
            ]
        },
        {
            "x": -4,
            "y": 20,
            "z": 1,
            "elements": [
                "projecte:matter_block@0"
            ]
        },
        {
            "x": -3,
            "y": 22,
            "z": 2,
            
            "elements": [
                "modularmachinery:blockcasing@0"
            ]
        },
        {
            "x": -2,
            "y": 22,
            "z": 2,
            
            "elements": [
                "modularmachinery:blockcasing@4"
            ]
        },
        {
            "x": 2,
            "y": 22,
            "z": 2,
            
            "elements": [
                "modularmachinery:blockcasing@4"
            ]
        },
        {
            "x": 3,
            "y": 22,
            "z": 2,
            
            "elements": [
                "modularmachinery:blockcasing@0"
            ]
        },
        {
            "x": 4,
            "y": 22,
            "z": 2,
            
            "elements": [
                "modularmachinery:blockcasing@0"
            ]
        },
        {
            "x": 4,
            "y": 20,
            "z": 1,
            "elements": [
                "projecte:matter_block@0"
            ]
        },
        {
            "x": -6,
            "y": 19,
            "z": 0,
            
            "elements": [
                "modularmachinery:blockcasing@4"
            ]
        },
        {
            "x": -5,
            "y": 19,
            "z": 0,
            
            "elements": [
                "modularmachinery:blockcasing@0"
            ]
        },
        {
            "x": -4,
            "y": 19,
            "z": 0,
            
            "elements": [
                "modularmachinery:blockcasing@0"
            ]
        },
        {
            "x": -3,
            "y": 21,
            "z": 1,
            "elements": [
                "projecte:matter_block@0"
            ]
        },
        {
            "x": -2,
            "y": 23,
            "z": 2,
            
            "elements": [
                "modularmachinery:blockcasing@0"
            ]
        },
        {
            "x": -2,
            "y": 21,
            "z": 1,
            "elements": [
                "projecte:matter_block@0"
            ]
        },
        {
            "x": -1,
            "y": 23,
            "z": 2,
            
            "elements": [
                "modularmachinery:blockcasing@0"
            ]
        },
        {
            "x": 0,
            "y": 23,
            "z": 2,
            
            "elements": [
                "modularmachinery:blockcasing@0"
            ]
        },
        {
            "x": 1,
            "y": 23,
            "z": 2,
            
            "elements": [
                "modularmachinery:blockcasing@0"
            ]
        },
        {
            "x": 2,
            "y": 23,
            "z": 2,
            
            "elements": [
                "modularmachinery:blockcasing@0"
            ]
        },
        {
            "x": 2,
            "y": 21,
            "z": 1,
            "elements": [
                "projecte:matter_block@0"
            ]
        },
        {
            "x": 3,
            "y": 21,
            "z": 1,
            "elements": [
                "projecte:matter_block@0"
            ]
        },
        {
            "x": 4,
            "y": 19,
            "z": 0,
            
            "elements": [
                "modularmachinery:blockcasing@0"
            ]
        },
        {
            "x": 5,
            "y": 19,
            "z": 0,
            
            "elements": [
                "modularmachinery:blockcasing@0"
            ]
        },
        {
            "x": 6,
            "y": 19,
            "z": 0,
            
            "elements": [
                "modularmachinery:blockcasing@4"
            ]
        },
        {
            "x": -4,
            "y": 20,
            "z": 0,
            
            "elements": [
                "modularmachinery:blockcasing@4"
            ]
        },
        {
            "x": -1,
            "y": 22,
            "z": 1,
            "elements": [
                "projecte:matter_block@0"
            ]
        },
        {
            "x": 0,
            "y": 22,
            "z": 1,
            "elements": [
                "projecte:matter_block@0"
            ]
        },
        {
            "x": 1,
            "y": 22,
            "z": 1,
            "elements": [
                "projecte:matter_block@0"
            ]
        },
        {
            "x": 4,
            "y": 20,
            "z": 0,
            
            "elements": [
                "modularmachinery:blockcasing@4"
            ]
        },
        {
            "x": -4,
            "y": 21,
            "z": 0,
            
            "elements": [
                "modularmachinery:blockcasing@0"
            ]
        },
        {
            "x": 0,
            "y": 23,
            "z": 1,
            
            "elements": [
                "modularmachinery:blockcasing@4"
            ]
        },
        {
            "x": 4,
            "y": 21,
            "z": 0,
            
            "elements": [
                "modularmachinery:blockcasing@0"
            ]
        },
        {
            "x": -3,
            "y": 22,
            "z": 0,
            
            "elements": [
                "modularmachinery:blockcasing@0"
            ]
        },
        {
            "x": -2,
            "y": 22,
            "z": 0,
            
            "elements": [
                "modularmachinery:blockcasing@0"
            ]
        },
        {
            "x": -1,
            "y": 22,
            "z": 0,
            
            "elements": [
                "modularmachinery:blockcasing@0"
            ]
        },
        {
            "x": 0,
            "y": 22,
            "z": 0,
            
            "elements": [
                "modularmachinery:blockcasing@4"
            ]
        },
        {
            "x": 1,
            "y": 22,
            "z": 0,
            
            "elements": [
                "modularmachinery:blockcasing@0"
            ]
        },
        {
            "x": 2,
            "y": 22,
            "z": 0,
            
            "elements": [
                "modularmachinery:blockcasing@0"
            ]
        },
        {
            "x": 3,
            "y": 22,
            "z": 0,
            
            "elements": [
                "modularmachinery:blockcasing@0"
            ]
        },
        {
            "x": 0,
            "y": 23,
            "z": 0,
            
            "elements": [
                "modularmachinery:blockcasing@0"
            ]
        },
        {
            "x": -2,
            "y": 0,
            "z": 4,
            
            "elements": [
                "modularmachinery:blockcasing@0"
            ]
        },
        {
            "x": -1,
            "y": 0,
            "z": 4,
            
            "elements": [
                "modularmachinery:blockcasing@0"
            ]
        },
        {
            "x": 0,
            "y": 0,
            "z": 4,
            
            "elements": [
                "modularmachinery:blockcasing@0"
            ]
        },
        {
            "x": 1,
            "y": 0,
            "z": 4,
            
            "elements": [
                "modularmachinery:blockcasing@0"
            ]
        },
        {
            "x": 2,
            "y": 0,
            "z": 4,
            
            "elements": [
                "modularmachinery:blockcasing@0"
            ]
        },
        {
            "x": -2,
            "y": 1,
            "z": 4,
            
            "elements": [
                "modularmachinery:blockcasing@0"
            ]
        },
        {
            "x": -1,
            "y": 1,
            "z": 4,
            "elements": [
                "projecte:matter_block@0"
            ]
        },
        {
            "x": 0,
            "y": 1,
            "z": 4,
            "elements": [
                "projecte:matter_block@0"
            ]
        },
        {
            "x": 1,
            "y": 1,
            "z": 4,
            "elements": [
                "projecte:matter_block@0"
            ]
        },
        {
            "x": 2,
            "y": 1,
            "z": 4,
            
            "elements": [
                "modularmachinery:blockcasing@0"
            ]
        },
        {
            "x": -2,
            "y": 2,
            "z": 4,
            
            "elements": [
                "modularmachinery:blockcasing@0"
            ]
        },
        {
            "x": -1,
            "y": 2,
            "z": 4,
            
            "elements": [
                "modularmachinery:blockcasing@4"
            ]
        },
        {
            "x": -2,
            "y": 0,
            "z": 3,
            
            "elements": [
                "modularmachinery:blockcasing@0"
            ]
        },
        {
            "x": 0,
            "y": 2,
            "z": 4,
            
            "elements": [
                "modularmachinery:blockcasing@0"
            ]
        },
        {
            "x": -1,
            "y": 0,
            "z": 3,
            "elements": [
                "projecte:matter_block@0"
            ]
        },
        {
            "x": 1,
            "y": 2,
            "z": 4,
            
            "elements": [
                "modularmachinery:blockcasing@4"
            ]
        },
        {
            "x": 0,
            "y": 0,
            "z": 3,
            "elements": [
                "projecte:matter_block@0"
            ]
        },
        {
            "x": 2,
            "y": 2,
            "z": 4,
            
            "elements": [
                "modularmachinery:blockcasing@0"
            ]
        },
        {
            "x": 1,
            "y": 0,
            "z": 3,
            "elements": [
                "projecte:matter_block@0"
            ]
        },
        {
            "x": 2,
            "y": 0,
            "z": 3,
            "elements": [
                "modularmachinery:blockenergyinputhatch@1"
            ]
        },
        {
            "x": -2,
            "y": 3,
            "z": 4,
            
            "elements": [
                "modularmachinery:blockcasing@0"
            ]
        },
        {
            "x": -1,
            "y": 3,
            "z": 4,
            
            "elements": [
                "modularmachinery:blockcasing@4"
            ]
        },
        {
            "x": -2,
            "y": 1,
            "z": 3,
            "elements": [
                "projecte:matter_block@0"
            ]
        },
        {
            "x": 0,
            "y": 3,
            "z": 4,
            "elements": [
                "projecte:matter_block@0"
            ]
        },
        {
            "x": -1,
            "y": 1,
            "z": 3,
            "elements": [
                "projecte:matter_block@0"
            ]
        },
        {
            "x": 1,
            "y": 3,
            "z": 4,
            
            "elements": [
                "modularmachinery:blockcasing@4"
            ]
        },
        {
            "x": 0,
            "y": 1,
            "z": 3,
            "elements": [
                "projecte:matter_block@0"
            ]
        },
        {
            "x": 2,
            "y": 3,
            "z": 4,
            
            "elements": [
                "modularmachinery:blockcasing@0"
            ]
        },
        {
            "x": 1,
            "y": 1,
            "z": 3,
            "elements": [
                "projecte:matter_block@0"
            ]
        },
        {
            "x": 2,
            "y": 1,
            "z": 3,
            "elements": [
                "projecte:matter_block@0"
            ]
        },
        {
            "x": -2,
            "y": 4,
            "z": 4,
            
            "elements": [
                "modularmachinery:blockcasing@0"
            ]
        },
        {
            "x": -2,
            "y": 2,
            "z": 3,
            
            "elements": [
                "modularmachinery:blockcasing@4"
            ]
        },
        {
            "x": -1,
            "y": 4,
            "z": 4,
            
            "elements": [
                "modularmachinery:blockcasing@0"
            ]
        },
        {
            "x": 0,
            "y": 4,
            "z": 4,
            
            "elements": [
                "modularmachinery:blockcasing@4"
            ]
        },
        {
            "x": -2,
            "y": 0,
            "z": 2,
            "elements": [
                "modularmachinery:blockoutputbus@1"
            ]
        },
        {
            "x": -1,
            "y": 0,
            "z": 2,
            "elements": [
                "projecte:matter_block@0"
            ]
        },
        {
            "x": 1,
            "y": 4,
            "z": 4,
            
            "elements": [
                "modularmachinery:blockcasing@0"
            ]
        },
        {
            "x": 2,
            "y": 4,
            "z": 4,
            
            "elements": [
                "modularmachinery:blockcasing@0"
            ]
        },
        {
            "x": 0,
            "y": 0,
            "z": 2,
            "elements": [
                "projecte:matter_block@0"
            ]
        },
        {
            "x": 2,
            "y": 2,
            "z": 3,
            
            "elements": [
                "modularmachinery:blockcasing@4"
            ]
        },
        {
            "x": 1,
            "y": 0,
            "z": 2,
            "elements": [
                "projecte:matter_block@0"
            ]
        },
        {
            "x": 2,
            "y": 0,
            "z": 2,
            "elements": [
                "modularmachinery:blockfluidinputhatch@2"
            ]
        },
        {
            "x": -2,
            "y": 5,
            "z": 4,
            
            "elements": [
                "modularmachinery:blockcasing@0"
            ]
        },
        {
            "x": -2,
            "y": 3,
            "z": 3,
            
            "elements": [
                "modularmachinery:blockcasing@4"
            ]
        },
        {
            "x": 0,
            "y": 5,
            "z": 4,
            
            "elements": [
                "modularmachinery:blockcasing@4"
            ]
        },
        {
            "x": -2,
            "y": 1,
            "z": 2,
            "elements": [
                "projecte:matter_block@0"
            ]
        },
        {
            "x": -1,
            "y": 1,
            "z": 2,
            "elements": [
                "projecte:matter_block@0"
            ]
        },
        {
            "x": 2,
            "y": 5,
            "z": 4,
            
            "elements": [
                "modularmachinery:blockcasing@0"
            ]
        },
        {
            "x": 0,
            "y": 1,
            "z": 2,
            "elements": [
                "projecte:matter_block@0"
            ]
        },
        {
            "x": 2,
            "y": 3,
            "z": 3,
            
            "elements": [
                "modularmachinery:blockcasing@4"
            ]
        },
        {
            "x": 1,
            "y": 1,
            "z": 2,
            "elements": [
                "projecte:matter_block@0"
            ]
        },
        {
            "x": 2,
            "y": 1,
            "z": 2,
            "elements": [
                "modularmachinery:blockinputbus@1"
            ]
        },
        {
            "x": -2,
            "y": 6,
            "z": 4,
            
            "elements": [
                "modularmachinery:blockcasing@4"
            ]
        },
        {
            "x": -2,
            "y": 4,
            "z": 3,
            
            "elements": [
                "modularmachinery:blockcasing@0"
            ]
        },
        {
            "x": -2,
            "y": 2,
            "z": 2,
            
            "elements": [
                "modularmachinery:blockcasing@0"
            ]
        },
        {
            "x": -1,
            "y": 4,
            "z": 3,
            
            "elements": [
                "modularmachinery:blockcasing@0"
            ]
        },
        {
            "x": 0,
            "y": 6,
            "z": 4,
            
            "elements": [
                "modularmachinery:blockcasing@0"
            ]
        },
        {
            "x": -2,
            "y": 0,
            "z": 1,
            
            "elements": [
                "modularmachinery:blockcasing@0"
            ]
        },
        {
            "x": 2,
            "y": 6,
            "z": 4,
            
            "elements": [
                "modularmachinery:blockcasing@4"
            ]
        },
        {
            "x": 1,
            "y": 4,
            "z": 3,
            
            "elements": [
                "modularmachinery:blockcasing@0"
            ]
        },
        {
            "x": -1,
            "y": 0,
            "z": 1,
            "elements": [
                "projecte:matter_block@0"
            ]
        },
        {
            "x": 2,
            "y": 4,
            "z": 3,
            
            "elements": [
                "modularmachinery:blockcasing@0"
            ]
        },
        {
            "x": 0,
            "y": 0,
            "z": 1,
            "elements": [
                "projecte:matter_block@0"
            ]
        },
        {
            "x": 2,
            "y": 2,
            "z": 2,
            
            "elements": [
                "modularmachinery:blockcasing@0"
            ]
        },
        {
            "x": 1,
            "y": 0,
            "z": 1,
            "elements": [
                "projecte:matter_block@0"
            ]
        },
        {
            "x": 2,
            "y": 0,
            "z": 1,
            
            "elements": [
                "modularmachinery:blockcasing@0"
            ]
        },
        {
            "x": -2,
            "y": 7,
            "z": 4,
            
            "elements": [
                "modularmachinery:blockcasing@0"
            ]
        },
        {
            "x": -2,
            "y": 3,
            "z": 2,
            "elements": [
                "projecte:matter_block@0"
            ]
        },
        {
            "x": -1,
            "y": 5,
            "z": 3,
            
            "elements": [
                "modularmachinery:blockcasing@4"
            ]
        },
        {
            "x": 0,
            "y": 7,
            "z": 4,
            
            "elements": [
                "modularmachinery:blockcasing@0"
            ]
        },
        {
            "x": -2,
            "y": 1,
            "z": 1,
            "elements": [
                "projecte:matter_block@0"
            ]
        },
        {
            "x": 2,
            "y": 7,
            "z": 4,
            
            "elements": [
                "modularmachinery:blockcasing@0"
            ]
        },
        {
            "x": 1,
            "y": 5,
            "z": 3,
            
            "elements": [
                "modularmachinery:blockcasing@4"
            ]
        },
        {
            "x": -1,
            "y": 1,
            "z": 1,
            "elements": [
                "projecte:matter_block@0"
            ]
        },
        {
            "x": 0,
            "y": 1,
            "z": 1,
            "elements": [
                "projecte:matter_block@0"
            ]
        },
        {
            "x": 2,
            "y": 3,
            "z": 2,
            "elements": [
                "projecte:matter_block@0"
            ]
        },
        {
            "x": 1,
            "y": 1,
            "z": 1,
            "elements": [
                "projecte:matter_block@0"
            ]
        },
        {
            "x": 2,
            "y": 1,
            "z": 1,
            "elements": [
                "projecte:matter_block@0"
            ]
        },
        {
            "x": -2,
            "y": 8,
            "z": 4,
            
            "elements": [
                "modularmachinery:blockcasing@4"
            ]
        },
        {
            "x": -1,
            "y": 8,
            "z": 4,
            
            "elements": [
                "modularmachinery:blockcasing@0"
            ]
        },
        {
            "x": -2,
            "y": 4,
            "z": 2,
            
            "elements": [
                "modularmachinery:blockcasing@4"
            ]
        },
        {
            "x": 0,
            "y": 8,
            "z": 4,
            
            "elements": [
                "modularmachinery:blockcasing@0"
            ]
        },
        {
            "x": -1,
            "y": 6,
            "z": 3,
            "elements": [
                "projecte:matter_block@0"
            ]
        },
        {
            "x": -2,
            "y": 2,
            "z": 1,
            
            "elements": [
                "modularmachinery:blockcasing@4"
            ]
        },
        {
            "x": 0,
            "y": 6,
            "z": 3,
            "elements": [
                "projecte:matter_block@0"
            ]
        },
        {
            "x": 1,
            "y": 8,
            "z": 4,
            
            "elements": [
                "modularmachinery:blockcasing@0"
            ]
        },
        {
            "x": 2,
            "y": 8,
            "z": 4,
            
            "elements": [
                "modularmachinery:blockcasing@4"
            ]
        },
        {
            "x": 1,
            "y": 6,
            "z": 3,
            "elements": [
                "projecte:matter_block@0"
            ]
        }
    ]}